File: ReciprocalSpaceMapAnalysis/Reciprocal Space Working/Lam_Ge_onSi_RLM_PIXcel.xrdml
<?xml version="1.0" encoding="UTF-8"?>
<xrdMeasurements xmlns="http://www.xrdml.com/XRDMeasurement/1.5" xmlns:xsi="http://www.w3.org/2001/XMLSchema-instance" xsi:schemaLocation="http://www.xrdml.com/XRDMeasurement/1.5 http://www.xrdml.com/XRDMeasurement/1.5/XRDMeasurement.xsd" status="Completed">
	<comment>
		<entry>Configuration=Hybrid + PIXcel, Owner=Arturas, Creation date=1/25/2011 11:33:53 AM</entry>
		<entry>Goniometer=PW3050/65 (Theta/2Theta); Minimum step size 2Theta:0.0001; Minimum step size Omega:0.0001</entry>
		<entry>Sample stage=MRD Cradle; Minimum step size Phi:0.01; Minimum step size Chi:0.01; Minimum step size X:0.01; Minimum step size Y:0.01; Minimum step size Z:0.001</entry>
		<entry>Diffractometer system=XPERT-PRO</entry>
		<entry>Measurement program=C:\XPERT2_USERS\mbraun7\RLM_PIXcel_01.xrdmp, Identifier={4D6D0D9B-7397-4470-9393-2DA596401032}</entry>
	</comment>
	<sample type="To be analyzed">
		<id></id>
		<name></name>
		<preparedBy></preparedBy>
	</sample>
	<xrdMeasurement measurementType="Area measurement" status="Completed" measurementStepAxis="Omega" sampleMode="Reflection">
		<comment>
			<entry/>
		</comment>
		<usedWavelength intended="K-Alpha 1">
			<kAlpha1 unit="Angstrom">1.5405980</kAlpha1>
			<kAlpha2 unit="Angstrom">1.5444260</kAlpha2>
			<kBeta unit="Angstrom">1.3922500</kBeta>
			<ratioKAlpha2KAlpha1>0.5000</ratioKAlpha2KAlpha1>
		</usedWavelength>
		<incidentBeamPath>
			<radius unit="mm">320.00</radius>
			<xRayTube id="1010048" name="Empyrean Cu LFF HR (9430 033 7310x) DK408103">
				<tension unit="kV">45</tension>
				<current unit="mA">40</current>
				<anodeMaterial>Cu</anodeMaterial>
				<focus type="Line">
					<length unit="mm">12.0</length>
					<width unit="mm">0.4</width>
					<takeOffAngle unit="deg">2.5</takeOffAngle>
				</focus>
			</xRayTube>
			<xRayMirror id="27090001" name="Inc. Beam Cu W/Si (hybrid MRD)" hybrid="true">
				<crystal type="Graded" shape="Parabolic">W/Si</crystal>
				<acceptanceAngle unit="deg">0.800</acceptanceAngle>
				<length unit="mm">60.0</length>
			</xRayMirror>
			<monochromator id="23090002" name="Hybrid monochr. 2xGe(220) for Cu" hybrid="true">
				<crystal type="Asymmetric" shape="Flat">Ge</crystal>
				<numberOfReflections>2</numberOfReflections>
				<hkl>
					<h>2</h>
					<k>2</k>
					<l>0</l>
				</hkl>
			</monochromator>
			<divergenceSlit id="22010004" name="Fixed slit 1/2Â°" xsi:type="fixedDivergenceSlitType">
				<distanceToSample unit="mm">220.00</distanceToSample>
				<height unit="mm">0.76</height>
			</divergenceSlit>
		</incidentBeamPath>
		<sampleOffset>
			<position axis="2Theta" unit="deg">0.0031</position>
			<position axis="Omega" unit="deg">0.2122</position>
			<position axis="Phi" unit="deg">-4.20</position>
			<position axis="Chi" unit="deg">-0.34</position>
		</sampleOffset>
		<diffractedBeamPath>
			<radius unit="mm">320.00</radius>
			<detector id="7010015" name="PIXcel1D detector" xsi:type="rtmsDetectorType">
				<phd>
					<lowerLevel unit="%">25.5</lowerLevel>
					<upperLevel unit="%">100.0</upperLevel>
				</phd>
				<mode>Scanning</mode>
				<activeLength unit="deg">2.5108</activeLength>
			</detector>
		</diffractedBeamPath>
		<measurementStepAxisCenter>
			<position axis="Omega" unit="deg">52.7200</position>
		</measurementStepAxisCenter>
		<scan appendNumber="0" mode="Continuous" scanAxis="2Theta" status="Completed">
			<header>
				<startTimeStamp>2016-06-23T14:43:29-07:00</startTimeStamp>
				<endTimeStamp>2016-06-23T14:43:38-07:00</endTimeStamp>
				<author>
					<name>user</name>
				</author>
				<source>
					<applicationSoftware version="4.2a">Data Collector</applicationSoftware>
					<instrumentControlSoftware version="2.1E 20110621">XPERT-PRO</instrumentControlSoftware>
					<instrumentID>0000000000030961</instrumentID>
				</source>
			</header>
			<scanAxisCenter>
				<position axis="2Theta" unit="deg">54.9088</position>
			</scanAxisCenter>
			<reflection>
				<material>Si [001]</material>
				<hkl>
					<h>-1</h>
					<k>-1</k>
					<l>3</l>
				</hkl>
				<unitCell>
					<alpha unit="deg">90.00000</alpha>
					<beta unit="deg">90.00000</beta>
					<gamma unit="deg">90.00000</gamma>
					<a unit="Angstrom">5.43119</a>
					<b unit="Angstrom">5.43119</b>
					<c unit="Angstrom">5.43119</c>
				</unitCell>
			</reflection>
			<dataPoints>
				<positions axis="2Theta" unit="deg">
					<startPosition>52.93924771</startPosition>
					<endPosition>56.87833249</endPosition>
				</positions>
				<positions axis="Omega" unit="deg">
					<commonPosition>51.2800</commonPosition>
				</positions>
				<positions axis="Phi" unit="deg">
					<commonPosition>0.00</commonPosition>
				</positions>
				<positions axis="Chi" unit="deg">
					<commonPosition>0.00</commonPosition>
				</positions>
				<positions axis="X" unit="mm">
					<commonPosition>0.00</commonPosition>
				</positions>
				<positions axis="Y" unit="mm">
					<commonPosition>0.00</commonPosition>
				</positions>
				<positions axis="Z" unit="mm">
					<commonPosition>8.075</commonPosition>
				</positions>
				<commonCountingTime unit="seconds">2.040</commonCountingTime>
				<intensities unit="counts">1 1 2 0 1 1 0 1 0 1 3 2 2 1 5 3 3 7 11 9 13 17 9 14 19 10 8 9 9 12 11 14 13 5 9 9 6 9 6 9 5 6 7 3 3 5 6 3 5 3 2 0 0 1 3 2 1 1 3 3 1 0 0 1 0 1 0 1 1 1 0 2 0 2 0 2 0 0 1 0 0 0 0 2 0 0 0 1 0 0 0 1 0 0 0 0 0 3 0 0 0 0 1 0 0 0 0 0 0 0 0 0 3 0 0 0 0 1 0 0 0 1 1 1 0 0 0 0 0 0 0 1 0 0 0 1 0 1 4 0 0 0 0 0 0 0 1 0 0 0 0 0 0 0 2 0 0 1 0 0 1 0 0 1 1 0 0 0 1 0 0 0 0 1 0 2 0 0 0 0 0 0 0 1 0 0 0 0 1 0 0 0 0 0 0 0 0 0 0 1 0</intensities>
			</dataPoints>
		</scan>
		<scan appendNumber="0" mode="Continuous" scanAxis="2Theta" status="Completed">
			<header>
				<startTimeStamp>2016-06-23T14:43:51-07:00</startTimeStamp>
				<endTimeStamp>2016-06-23T14:43:59-07:00</endTimeStamp>
				<author>
					<name>user</name>
				</author>
				<source>
					<applicationSoftware version="4.2a">Data Collector</applicationSoftware>
					<instrumentControlSoftware version="2.1E 20110621">XPERT-PRO</instrumentControlSoftware>
					<instrumentID>0000000000030961</instrumentID>
				</source>
			</header>
			<scanAxisCenter>
				<position axis="2Theta" unit="deg">54.9088</position>
			</scanAxisCenter>
			<reflection>
				<material>Si [001]</material>
				<hkl>
					<h>-1</h>
					<k>-1</k>
					<l>3</l>
				</hkl>
				<unitCell>
					<alpha unit="deg">90.00000</alpha>
					<beta unit="deg">90.00000</beta>
					<gamma unit="deg">90.00000</gamma>
					<a unit="Angstrom">5.43119</a>
					<b unit="Angstrom">5.43119</b>
					<c unit="Angstrom">5.43119</c>
				</unitCell>
			</reflection>
			<dataPoints>
				<positions axis="2Theta" unit="deg">
					<startPosition>52.93924771</startPosition>
					<endPosition>56.87833249</endPosition>
				</positions>
				<positions axis="Omega" unit="deg">
					<commonPosition>51.3000</commonPosition>
				</positions>
				<positions axis="Phi" unit="deg">
					<commonPosition>0.00</commonPosition>
				</positions>
				<positions axis="Chi" unit="deg">
					<commonPosition>0.00</commonPosition>
				</positions>
				<positions axis="X" unit="mm">
					<commonPosition>0.00</commonPosition>
				</positions>
				<positions axis="Y" unit="mm">
					<commonPosition>0.00</commonPosition>
				</positions>
				<positions axis="Z" unit="mm">
					<commonPosition>8.075</commonPosition>
				</positions>
				<commonCountingTime unit="seconds">2.040</commonCountingTime>
				<intensities unit="counts">4 1 0 0 0 3 0 0 3 7 2 5 4 3 2 4 6 3 11 11 14 12 11 10 15 15 16 17 18 13 9 10 20 11 7 14 14 11 9 8 5 3 6 2 5 5 7 10 1 3 3 7 4 3 1 1 0 3 1 2 0 1 1 0 0 0 4 0 0 3 0 1 0 0 0 1 2 1 0 0 0 2 2 1 0 0 1 0 0 2 0 1 1 0 0 0 0 0 0 1 0 0 0 0 0 0 0 0 0 0 1 0 0 0 0 0 0 0 0 1 0 0 1 1 1 0 1 0 0 0 0 0 0 0 0 0 0 2 1 0 0 0 0 0 0 1 1 0 1 0 0 2 1 0 0 0 0 0 0 1 0 0 0 0 0 2 3 0 0 1 1 1 0 1 1 0 0 0 1 0 2 0 0 0 0 0 0 0 0 0 1 0 1 0 0 1 0 1 0 0 2</intensities>
			</dataPoints>
		</scan>
		<scan appendNumber="0" mode="Continuous" scanAxis="2Theta" status="Completed">
			<header>
				<startTimeStamp>2016-06-23T14:44:09-07:00</startTimeStamp>
				<endTimeStamp>2016-06-23T14:44:17-07:00</endTimeStamp>
				<author>
					<name>user</name>
				</author>
				<source>
					<applicationSoftware version="4.2a">Data Collector</applicationSoftware>
					<instrumentControlSoftware version="2.1E 20110621">XPERT-PRO</instrumentControlSoftware>
					<instrumentID>0000000000030961</instrumentID>
				</source>
			</header>
			<scanAxisCenter>
				<position axis="2Theta" unit="deg">54.9088</position>
			</scanAxisCenter>
			<reflection>
				<material>Si [001]</material>
				<hkl>
					<h>-1</h>
					<k>-1</k>
					<l>3</l>
				</hkl>
				<unitCell>
					<alpha unit="deg">90.00000</alpha>
					<beta unit="deg">90.00000</beta>
					<gamma unit="deg">90.00000</gamma>
					<a unit="Angstrom">5.43119</a>
					<b unit="Angstrom">5.43119</b>
					<c unit="Angstrom">5.43119</c>
				</unitCell>
			</reflection>
			<dataPoints>
				<positions axis="2Theta" unit="deg">
					<startPosition>52.93924771</startPosition>
					<endPosition>56.87833249</endPosition>
				</positions>
				<positions axis="Omega" unit="deg">
					<commonPosition>51.3200</commonPosition>
				</positions>
				<positions axis="Phi" unit="deg">
					<commonPosition>0.00</commonPosition>
				</positions>
				<positions axis="Chi" unit="deg">
					<commonPosition>0.00</commonPosition>
				</positions>
				<positions axis="X" unit="mm">
					<commonPosition>0.00</commonPosition>
				</positions>
				<positions axis="Y" unit="mm">
					<commonPosition>0.00</commonPosition>
				</positions>
				<positions axis="Z" unit="mm">
					<commonPosition>8.075</commonPosition>
				</positions>
				<commonCountingTime unit="seconds">2.040</commonCountingTime>
				<intensities unit="counts">0 3 1 2 0 0 1 6 3 2 1 5 1 7 10 2 6 18 13 10 14 7 18 3 14 21 11 19 13 12 13 7 19 15 9 10 10 9 12 8 8 7 2 8 5 9 8 4 5 4 4 0 1 1 4 0 5 1 5 3 1 0 2 0 0 0 1 0 1 1 0 1 0 1 2 1 0 0 1 1 0 1 0 0 0 0 0 1 0 1 0 0 0 0 1 0 0 0 1 0 0 0 1 2 0 1 0 0 0 1 2 0 1 0 0 0 0 0 0 0 2 0 0 0 0 1 1 0 0 0 0 0 1 0 0 3 0 0 0 0 1 0 0 0 0 0 0 0 0 0 0 0 0 1 0 1 0 0 0 0 2 0 0 0 2 0 0 1 0 0 0 0 0 2 0 0 0 0 0 0 0 0 0 0 0 1 0 0 0 0 1 0 1 0 0 0 0 1 0 1 3</intensities>
			</dataPoints>
		</scan>
		<scan appendNumber="0" mode="Continuous" scanAxis="2Theta" status="Completed">
			<header>
				<startTimeStamp>2016-06-23T14:44:32-07:00</startTimeStamp>
				<endTimeStamp>2016-06-23T14:44:40-07:00</endTimeStamp>
				<author>
					<name>user</name>
				</author>
				<source>
					<applicationSoftware version="4.2a">Data Collector</applicationSoftware>
					<instrumentControlSoftware version="2.1E 20110621">XPERT-PRO</instrumentControlSoftware>
					<instrumentID>0000000000030961</instrumentID>
				</source>
			</header>
			<scanAxisCenter>
				<position axis="2Theta" unit="deg">54.9088</position>
			</scanAxisCenter>
			<reflection>
				<material>Si [001]</material>
				<hkl>
					<h>-1</h>
					<k>-1</k>
					<l>3</l>
				</hkl>
				<unitCell>
					<alpha unit="deg">90.00000</alpha>
					<beta unit="deg">90.00000</beta>
					<gamma unit="deg">90.00000</gamma>
					<a unit="Angstrom">5.43119</a>
					<b unit="Angstrom">5.43119</b>
					<c unit="Angstrom">5.43119</c>
				</unitCell>
			</reflection>
			<dataPoints>
				<positions axis="2Theta" unit="deg">
					<startPosition>52.93924771</startPosition>
					<endPosition>56.87833249</endPosition>
				</positions>
				<positions axis="Omega" unit="deg">
					<commonPosition>51.3400</commonPosition>
				</positions>
				<positions axis="Phi" unit="deg">
					<commonPosition>0.00</commonPosition>
				</positions>
				<positions axis="Chi" unit="deg">
					<commonPosition>0.00</commonPosition>
				</positions>
				<positions axis="X" unit="mm">
					<commonPosition>0.00</commonPosition>
				</positions>
				<positions axis="Y" unit="mm">
					<commonPosition>0.00</commonPosition>
				</positions>
				<positions axis="Z" unit="mm">
					<commonPosition>8.075</commonPosition>
				</positions>
				<commonCountingTime unit="seconds">2.040</commonCountingTime>
				<intensities unit="counts">0 7 6 3 4 2 1 1 5 5 7 2 5 6 1 6 5 7 11 8 10 9 13 10 19 17 16 27 25 17 20 20 17 24 16 19 12 13 5 8 14 11 7 4 5 5 9 5 4 5 3 2 4 2 1 4 3 0 3 1 1 0 1 1 0 0 0 0 0 0 1 0 1 0 0 0 0 1 2 1 0 0 0 0 0 0 0 1 0 0 2 1 0 0 3 1 0 0 0 0 0 1 0 0 0 3 1 0 0 0 0 1 0 0 0 0 1 1 0 0 0 0 1 0 0 0 0 0 3 0 0 0 0 1 1 0 0 0 0 0 0 0 0 0 0 0 0 0 0 0 0 0 0 0 0 1 1 0 0 0 1 1 3 0 0 0 0 0 0 0 0 0 1 0 0 1 0 0 0 0 0 0 0 1 0 0 0 0 0 1 1 0 0 3 0 1 0 0 0 0 0</intensities>
			</dataPoints>
		</scan>
		<scan appendNumber="0" mode="Continuous" scanAxis="2Theta" status="Completed">
			<header>
				<startTimeStamp>2016-06-23T14:44:58-07:00</startTimeStamp>
				<endTimeStamp>2016-06-23T14:45:07-07:00</endTimeStamp>
				<author>
					<name>user</name>
				</author>
				<source>
					<applicationSoftware version="4.2a">Data Collector</applicationSoftware>
					<instrumentControlSoftware version="2.1E 20110621">XPERT-PRO</instrumentControlSoftware>
					<instrumentID>0000000000030961</instrumentID>
				</source>
			</header>
			<scanAxisCenter>
				<position axis="2Theta" unit="deg">54.9088</position>
			</scanAxisCenter>
			<reflection>
				<material>Si [001]</material>
				<hkl>
					<h>-1</h>
					<k>-1</k>
					<l>3</l>
				</hkl>
				<unitCell>
					<alpha unit="deg">90.00000</alpha>
					<beta unit="deg">90.00000</beta>
					<gamma unit="deg">90.00000</gamma>
					<a unit="Angstrom">5.43119</a>
					<b unit="Angstrom">5.43119</b>
					<c unit="Angstrom">5.43119</c>
				</unitCell>
			</reflection>
			<dataPoints>
				<positions axis="2Theta" unit="deg">
					<startPosition>52.93924771</startPosition>
					<endPosition>56.87833249</endPosition>
				</positions>
				<positions axis="Omega" unit="deg">
					<commonPosition>51.3600</commonPosition>
				</positions>
				<positions axis="Phi" unit="deg">
					<commonPosition>0.00</commonPosition>
				</positions>
				<positions axis="Chi" unit="deg">
					<commonPosition>0.00</commonPosition>
				</positions>
				<positions axis="X" unit="mm">
					<commonPosition>0.00</commonPosition>
				</positions>
				<positions axis="Y" unit="mm">
					<commonPosition>0.00</commonPosition>
				</positions>
				<positions axis="Z" unit="mm">
					<commonPosition>8.075</commonPosition>
				</positions>
				<commonCountingTime unit="seconds">2.040</commonCountingTime>
				<intensities unit="counts">0 0 3 2 1 2 1 8 4 6 5 4 0 3 8 8 11 8 8 13 4 17 19 24 17 21 16 16 14 20 24 20 15 13 25 20 8 21 9 15 9 17 12 9 6 8 5 0 10 2 3 5 4 1 5 2 3 4 3 0 0 1 0 0 0 1 1 0 1 2 0 0 2 0 0 1 1 2 2 2 3 1 0 2 0 1 2 0 0 2 1 0 0 1 0 0 0 1 1 0 1 0 0 0 0 0 1 0 0 0 0 0 0 0 0 1 0 0 1 0 0 0 0 0 0 0 0 0 0 0 1 0 0 1 1 0 0 0 0 0 0 1 0 0 0 1 0 0 0 2 1 0 0 0 0 2 0 2 0 0 0 0 0 2 0 0 0 0 0 0 0 1 0 1 0 0 0 0 0 0 0 1 0 0 1 0 0 0 0 0 0 0 1 0 0 0 2 1 1 0 0</intensities>
			</dataPoints>
		</scan>
		<scan appendNumber="0" mode="Continuous" scanAxis="2Theta" status="Completed">
			<header>
				<startTimeStamp>2016-06-23T14:45:23-07:00</startTimeStamp>
				<endTimeStamp>2016-06-23T14:45:32-07:00</endTimeStamp>
				<author>
					<name>user</name>
				</author>
				<source>
					<applicationSoftware version="4.2a">Data Collector</applicationSoftware>
					<instrumentControlSoftware version="2.1E 20110621">XPERT-PRO</instrumentControlSoftware>
					<instrumentID>0000000000030961</instrumentID>
				</source>
			</header>
			<scanAxisCenter>
				<position axis="2Theta" unit="deg">54.9088</position>
			</scanAxisCenter>
			<reflection>
				<material>Si [001]</material>
				<hkl>
					<h>-1</h>
					<k>-1</k>
					<l>3</l>
				</hkl>
				<unitCell>
					<alpha unit="deg">90.00000</alpha>
					<beta unit="deg">90.00000</beta>
					<gamma unit="deg">90.00000</gamma>
					<a unit="Angstrom">5.43119</a>
					<b unit="Angstrom">5.43119</b>
					<c unit="Angstrom">5.43119</c>
				</unitCell>
			</reflection>
			<dataPoints>
				<positions axis="2Theta" unit="deg">
					<startPosition>52.93924771</startPosition>
					<endPosition>56.87833249</endPosition>
				</positions>
				<positions axis="Omega" unit="deg">
					<commonPosition>51.3800</commonPosition>
				</positions>
				<positions axis="Phi" unit="deg">
					<commonPosition>0.00</commonPosition>
				</positions>
				<positions axis="Chi" unit="deg">
					<commonPosition>0.00</commonPosition>
				</positions>
				<positions axis="X" unit="mm">
					<commonPosition>0.00</commonPosition>
				</positions>
				<positions axis="Y" unit="mm">
					<commonPosition>0.00</commonPosition>
				</positions>
				<positions axis="Z" unit="mm">
					<commonPosition>8.075</commonPosition>
				</positions>
				<commonCountingTime unit="seconds">2.040</commonCountingTime>
				<intensities unit="counts">5 2 2 4 3 1 2 4 4 5 6 3 0 6 10 8 7 8 14 16 10 13 16 11 17 26 27 30 20 24 23 17 20 11 19 18 17 21 15 15 15 5 10 10 2 3 7 6 3 1 6 1 4 3 8 0 2 2 4 2 0 0 1 0 6 0 4 1 0 0 0 0 1 0 1 0 1 2 0 0 0 0 2 0 0 0 0 0 0 0 0 0 0 1 1 0 1 2 0 0 0 0 0 1 2 0 0 1 2 1 0 1 0 0 0 0 0 0 0 0 0 0 1 0 0 0 0 0 0 0 1 0 0 0 0 2 0 0 0 0 0 0 1 0 0 0 1 0 0 0 3 0 0 0 1 0 0 0 0 1 0 0 0 0 1 0 0 0 0 2 1 0 0 0 1 0 1 0 0 1 0 0 0 1 0 0 0 0 0 2 1 0 0 0 0 0 0 1 0 0 2</intensities>
			</dataPoints>
		</scan>
		<scan appendNumber="0" mode="Continuous" scanAxis="2Theta" status="Completed">
			<header>
				<startTimeStamp>2016-06-23T14:45:49-07:00</startTimeStamp>
				<endTimeStamp>2016-06-23T14:45:57-07:00</endTimeStamp>
				<author>
					<name>user</name>
				</author>
				<source>
					<applicationSoftware version="4.2a">Data Collector</applicationSoftware>
					<instrumentControlSoftware version="2.1E 20110621">XPERT-PRO</instrumentControlSoftware>
					<instrumentID>0000000000030961</instrumentID>
				</source>
			</header>
			<scanAxisCenter>
				<position axis="2Theta" unit="deg">54.9088</position>
			</scanAxisCenter>
			<reflection>
				<material>Si [001]</material>
				<hkl>
					<h>-1</h>
					<k>-1</k>
					<l>3</l>
				</hkl>
				<unitCell>
					<alpha unit="deg">90.00000</alpha>
					<beta unit="deg">90.00000</beta>
					<gamma unit="deg">90.00000</gamma>
					<a unit="Angstrom">5.43119</a>
					<b unit="Angstrom">5.43119</b>
					<c unit="Angstrom">5.43119</c>
				</unitCell>
			</reflection>
			<dataPoints>
				<positions axis="2Theta" unit="deg">
					<startPosition>52.93924771</startPosition>
					<endPosition>56.87833249</endPosition>
				</positions>
				<positions axis="Omega" unit="deg">
					<commonPosition>51.4000</commonPosition>
				</positions>
				<positions axis="Phi" unit="deg">
					<commonPosition>0.00</commonPosition>
				</positions>
				<positions axis="Chi" unit="deg">
					<commonPosition>0.00</commonPosition>
				</positions>
				<positions axis="X" unit="mm">
					<commonPosition>0.00</commonPosition>
				</positions>
				<positions axis="Y" unit="mm">
					<commonPosition>0.00</commonPosition>
				</positions>
				<positions axis="Z" unit="mm">
					<commonPosition>8.075</commonPosition>
				</positions>
				<commonCountingTime unit="seconds">2.040</commonCountingTime>
				<intensities unit="counts">0 1 2 1 1 0 3 0 4 5 2 3 5 7 12 9 7 14 16 18 7 12 18 24 25 27 22 26 28 39 29 23 27 21 22 14 30 12 12 21 13 17 11 13 7 9 8 9 11 8 2 4 2 4 4 0 0 1 2 0 5 4 0 4 0 5 1 0 0 1 1 1 0 0 0 0 0 0 1 0 2 2 0 0 2 1 0 0 0 1 0 0 0 1 0 0 1 0 1 2 0 0 0 0 0 0 1 1 0 1 0 0 0 0 0 0 0 0 0 0 0 0 0 0 0 0 0 0 0 1 0 0 0 2 0 0 2 0 0 3 0 1 0 0 0 0 0 0 0 0 0 0 0 0 1 0 0 1 0 0 0 0 0 0 0 0 0 1 0 0 0 0 2 0 0 0 0 0 0 0 0 0 0 0 0 1 0 0 0 0 0 0 0 0 0 3 0 2 0 0 0</intensities>
			</dataPoints>
		</scan>
		<scan appendNumber="0" mode="Continuous" scanAxis="2Theta" status="Completed">
			<header>
				<startTimeStamp>2016-06-23T14:46:11-07:00</startTimeStamp>
				<endTimeStamp>2016-06-23T14:46:19-07:00</endTimeStamp>
				<author>
					<name>user</name>
				</author>
				<source>
					<applicationSoftware version="4.2a">Data Collector</applicationSoftware>
					<instrumentControlSoftware version="2.1E 20110621">XPERT-PRO</instrumentControlSoftware>
					<instrumentID>0000000000030961</instrumentID>
				</source>
			</header>
			<scanAxisCenter>
				<position axis="2Theta" unit="deg">54.9088</position>
			</scanAxisCenter>
			<reflection>
				<material>Si [001]</material>
				<hkl>
					<h>-1</h>
					<k>-1</k>
					<l>3</l>
				</hkl>
				<unitCell>
					<alpha unit="deg">90.00000</alpha>
					<beta unit="deg">90.00000</beta>
					<gamma unit="deg">90.00000</gamma>
					<a unit="Angstrom">5.43119</a>
					<b unit="Angstrom">5.43119</b>
					<c unit="Angstrom">5.43119</c>
				</unitCell>
			</reflection>
			<dataPoints>
				<positions axis="2Theta" unit="deg">
					<startPosition>52.93924771</startPosition>
					<endPosition>56.87833249</endPosition>
				</positions>
				<positions axis="Omega" unit="deg">
					<commonPosition>51.4200</commonPosition>
				</positions>
				<positions axis="Phi" unit="deg">
					<commonPosition>0.00</commonPosition>
				</positions>
				<positions axis="Chi" unit="deg">
					<commonPosition>0.00</commonPosition>
				</positions>
				<positions axis="X" unit="mm">
					<commonPosition>0.00</commonPosition>
				</positions>
				<positions axis="Y" unit="mm">
					<commonPosition>0.00</commonPosition>
				</positions>
				<positions axis="Z" unit="mm">
					<commonPosition>8.075</commonPosition>
				</positions>
				<commonCountingTime unit="seconds">2.040</commonCountingTime>
				<intensities unit="counts">1 2 0 0 3 4 6 2 4 3 3 6 5 5 7 10 10 14 9 15 15 17 12 15 18 23 35 38 33 28 34 18 31 34 27 24 18 20 17 15 20 7 7 8 15 6 12 4 3 8 5 3 4 6 2 3 2 2 1 5 0 5 1 2 0 0 2 0 0 0 3 0 2 0 2 1 1 1 0 0 1 0 1 0 1 1 0 0 0 0 0 0 0 0 0 0 2 0 0 1 0 0 1 0 0 0 1 0 2 0 1 0 2 0 1 0 1 0 0 0 0 0 0 0 0 1 1 0 0 0 0 0 0 0 1 1 0 0 0 0 0 0 0 1 0 1 0 0 0 0 1 0 2 0 0 1 0 1 0 1 0 1 1 0 0 1 0 0 0 2 0 0 0 0 0 0 0 1 1 0 0 1 1 0 1 0 0 0 1 0 0 0 0 0 0 0 0 0 0 2 0</intensities>
			</dataPoints>
		</scan>
		<scan appendNumber="0" mode="Continuous" scanAxis="2Theta" status="Completed">
			<header>
				<startTimeStamp>2016-06-23T14:46:36-07:00</startTimeStamp>
				<endTimeStamp>2016-06-23T14:46:45-07:00</endTimeStamp>
				<author>
					<name>user</name>
				</author>
				<source>
					<applicationSoftware version="4.2a">Data Collector</applicationSoftware>
					<instrumentControlSoftware version="2.1E 20110621">XPERT-PRO</instrumentControlSoftware>
					<instrumentID>0000000000030961</instrumentID>
				</source>
			</header>
			<scanAxisCenter>
				<position axis="2Theta" unit="deg">54.9088</position>
			</scanAxisCenter>
			<reflection>
				<material>Si [001]</material>
				<hkl>
					<h>-1</h>
					<k>-1</k>
					<l>3</l>
				</hkl>
				<unitCell>
					<alpha unit="deg">90.00000</alpha>
					<beta unit="deg">90.00000</beta>
					<gamma unit="deg">90.00000</gamma>
					<a unit="Angstrom">5.43119</a>
					<b unit="Angstrom">5.43119</b>
					<c unit="Angstrom">5.43119</c>
				</unitCell>
			</reflection>
			<dataPoints>
				<positions axis="2Theta" unit="deg">
					<startPosition>52.93924771</startPosition>
					<endPosition>56.87833249</endPosition>
				</positions>
				<positions axis="Omega" unit="deg">
					<commonPosition>51.4400</commonPosition>
				</positions>
				<positions axis="Phi" unit="deg">
					<commonPosition>0.00</commonPosition>
				</positions>
				<positions axis="Chi" unit="deg">
					<commonPosition>0.00</commonPosition>
				</positions>
				<positions axis="X" unit="mm">
					<commonPosition>0.00</commonPosition>
				</positions>
				<positions axis="Y" unit="mm">
					<commonPosition>0.00</commonPosition>
				</positions>
				<positions axis="Z" unit="mm">
					<commonPosition>8.075</commonPosition>
				</positions>
				<commonCountingTime unit="seconds">2.040</commonCountingTime>
				<intensities unit="counts">5 0 0 2 1 3 3 1 4 6 5 5 3 6 11 3 12 5 12 10 11 15 18 18 24 20 26 39 27 33 24 28 32 21 20 21 22 27 22 18 20 14 15 17 10 8 12 10 9 7 4 3 3 9 6 6 1 4 3 3 2 4 1 2 1 4 1 2 1 0 1 0 1 0 0 0 2 0 1 2 0 0 0 0 0 0 0 0 0 0 0 0 0 1 1 0 0 3 0 0 0 0 0 0 1 1 0 0 0 0 1 1 1 0 0 0 1 0 0 0 0 0 0 0 1 0 0 0 0 1 0 0 0 0 0 0 0 0 0 1 0 1 0 0 0 2 0 1 0 1 0 0 0 0 0 0 0 0 0 0 0 1 0 1 1 0 0 0 0 0 0 1 0 0 0 1 0 0 1 0 0 1 0 1 0 0 1 0 0 0 0 0 0 0 0 0 0 0 1 0 0</intensities>
			</dataPoints>
		</scan>
		<scan appendNumber="0" mode="Continuous" scanAxis="2Theta" status="Completed">
			<header>
				<startTimeStamp>2016-06-23T14:46:56-07:00</startTimeStamp>
				<endTimeStamp>2016-06-23T14:47:05-07:00</endTimeStamp>
				<author>
					<name>user</name>
				</author>
				<source>
					<applicationSoftware version="4.2a">Data Collector</applicationSoftware>
					<instrumentControlSoftware version="2.1E 20110621">XPERT-PRO</instrumentControlSoftware>
					<instrumentID>0000000000030961</instrumentID>
				</source>
			</header>
			<scanAxisCenter>
				<position axis="2Theta" unit="deg">54.9088</position>
			</scanAxisCenter>
			<reflection>
				<material>Si [001]</material>
				<hkl>
					<h>-1</h>
					<k>-1</k>
					<l>3</l>
				</hkl>
				<unitCell>
					<alpha unit="deg">90.00000</alpha>
					<beta unit="deg">90.00000</beta>
					<gamma unit="deg">90.00000</gamma>
					<a unit="Angstrom">5.43119</a>
					<b unit="Angstrom">5.43119</b>
					<c unit="Angstrom">5.43119</c>
				</unitCell>
			</reflection>
			<dataPoints>
				<positions axis="2Theta" unit="deg">
					<startPosition>52.93924771</startPosition>
					<endPosition>56.87833249</endPosition>
				</positions>
				<positions axis="Omega" unit="deg">
					<commonPosition>51.4600</commonPosition>
				</positions>
				<positions axis="Phi" unit="deg">
					<commonPosition>0.00</commonPosition>
				</positions>
				<positions axis="Chi" unit="deg">
					<commonPosition>0.00</commonPosition>
				</positions>
				<positions axis="X" unit="mm">
					<commonPosition>0.00</commonPosition>
				</positions>
				<positions axis="Y" unit="mm">
					<commonPosition>0.00</commonPosition>
				</positions>
				<positions axis="Z" unit="mm">
					<commonPosition>8.075</commonPosition>
				</positions>
				<commonCountingTime unit="seconds">2.040</commonCountingTime>
				<intensities unit="counts">0 3 3 1 3 5 7 4 1 6 8 7 7 4 11 13 6 9 9 16 13 14 24 25 30 36 25 26 35 54 34 33 34 29 31 19 28 35 26 25 20 17 16 10 10 13 12 9 12 6 4 10 6 3 6 2 3 0 5 0 1 5 1 3 2 2 0 0 0 1 2 0 2 4 0 0 1 0 0 1 0 1 0 1 1 0 1 0 3 1 1 0 1 0 1 0 0 2 0 0 1 0 0 0 0 1 1 0 0 0 0 0 0 0 0 2 0 0 0 0 0 0 0 0 0 1 0 0 0 1 0 2 0 0 0 0 0 0 0 0 0 1 0 0 0 0 0 0 1 2 0 0 0 0 0 0 1 0 0 0 0 0 0 1 1 0 0 0 0 0 0 0 0 1 0 0 0 0 0 0 1 1 1 0 0 0 0 1 0 0 0 2 0 0 0 1 0 0 0 0 0</intensities>
			</dataPoints>
		</scan>
		<scan appendNumber="0" mode="Continuous" scanAxis="2Theta" status="Completed">
			<header>
				<startTimeStamp>2016-06-23T14:47:24-07:00</startTimeStamp>
				<endTimeStamp>2016-06-23T14:47:32-07:00</endTimeStamp>
				<author>
					<name>user</name>
				</author>
				<source>
					<applicationSoftware version="4.2a">Data Collector</applicationSoftware>
					<instrumentControlSoftware version="2.1E 20110621">XPERT-PRO</instrumentControlSoftware>
					<instrumentID>0000000000030961</instrumentID>
				</source>
			</header>
			<scanAxisCenter>
				<position axis="2Theta" unit="deg">54.9088</position>
			</scanAxisCenter>
			<reflection>
				<material>Si [001]</material>
				<hkl>
					<h>-1</h>
					<k>-1</k>
					<l>3</l>
				</hkl>
				<unitCell>
					<alpha unit="deg">90.00000</alpha>
					<beta unit="deg">90.00000</beta>
					<gamma unit="deg">90.00000</gamma>
					<a unit="Angstrom">5.43119</a>
					<b unit="Angstrom">5.43119</b>
					<c unit="Angstrom">5.43119</c>
				</unitCell>
			</reflection>
			<dataPoints>
				<positions axis="2Theta" unit="deg">
					<startPosition>52.93924771</startPosition>
					<endPosition>56.87833249</endPosition>
				</positions>
				<positions axis="Omega" unit="deg">
					<commonPosition>51.4800</commonPosition>
				</positions>
				<positions axis="Phi" unit="deg">
					<commonPosition>0.00</commonPosition>
				</positions>
				<positions axis="Chi" unit="deg">
					<commonPosition>0.00</commonPosition>
				</positions>
				<positions axis="X" unit="mm">
					<commonPosition>0.00</commonPosition>
				</positions>
				<positions axis="Y" unit="mm">
					<commonPosition>0.00</commonPosition>
				</positions>
				<positions axis="Z" unit="mm">
					<commonPosition>8.075</commonPosition>
				</positions>
				<commonCountingTime unit="seconds">2.040</commonCountingTime>
				<intensities unit="counts">2 2 0 0 1 1 1 4 1 5 1 10 10 6 6 6 3 7 15 21 11 26 17 24 37 29 46 30 32 38 40 40 36 28 28 35 26 24 27 28 25 24 10 12 17 15 14 7 7 8 8 11 8 4 3 0 5 3 6 1 0 1 1 4 1 2 1 4 4 1 1 2 0 1 1 2 1 1 0 0 0 0 1 1 2 0 0 0 0 0 1 1 2 0 0 0 0 0 0 1 0 0 0 0 0 0 0 1 0 0 3 0 1 0 0 0 0 0 0 0 0 0 0 2 0 0 0 0 2 1 0 1 0 0 1 0 0 0 1 0 0 0 0 1 0 0 0 0 0 0 2 0 1 0 0 1 1 0 1 1 0 0 0 1 0 0 0 1 0 1 1 0 0 0 0 1 0 0 0 0 1 0 0 0 0 1 1 0 1 1 1 0 0 1 0 0 1 0 0 0 0</intensities>
			</dataPoints>
		</scan>
		<scan appendNumber="0" mode="Continuous" scanAxis="2Theta" status="Completed">
			<header>
				<startTimeStamp>2016-06-23T14:47:50-07:00</startTimeStamp>
				<endTimeStamp>2016-06-23T14:47:58-07:00</endTimeStamp>
				<author>
					<name>user</name>
				</author>
				<source>
					<applicationSoftware version="4.2a">Data Collector</applicationSoftware>
					<instrumentControlSoftware version="2.1E 20110621">XPERT-PRO</instrumentControlSoftware>
					<instrumentID>0000000000030961</instrumentID>
				</source>
			</header>
			<scanAxisCenter>
				<position axis="2Theta" unit="deg">54.9088</position>
			</scanAxisCenter>
			<reflection>
				<material>Si [001]</material>
				<hkl>
					<h>-1</h>
					<k>-1</k>
					<l>3</l>
				</hkl>
				<unitCell>
					<alpha unit="deg">90.00000</alpha>
					<beta unit="deg">90.00000</beta>
					<gamma unit="deg">90.00000</gamma>
					<a unit="Angstrom">5.43119</a>
					<b unit="Angstrom">5.43119</b>
					<c unit="Angstrom">5.43119</c>
				</unitCell>
			</reflection>
			<dataPoints>
				<positions axis="2Theta" unit="deg">
					<startPosition>52.93924771</startPosition>
					<endPosition>56.87833249</endPosition>
				</positions>
				<positions axis="Omega" unit="deg">
					<commonPosition>51.5000</commonPosition>
				</positions>
				<positions axis="Phi" unit="deg">
					<commonPosition>0.00</commonPosition>
				</positions>
				<positions axis="Chi" unit="deg">
					<commonPosition>0.00</commonPosition>
				</positions>
				<positions axis="X" unit="mm">
					<commonPosition>0.00</commonPosition>
				</positions>
				<positions axis="Y" unit="mm">
					<commonPosition>0.00</commonPosition>
				</positions>
				<positions axis="Z" unit="mm">
					<commonPosition>8.075</commonPosition>
				</positions>
				<commonCountingTime unit="seconds">2.040</commonCountingTime>
				<intensities unit="counts">0 2 1 0 2 1 5 5 4 6 7 3 6 3 3 11 15 6 10 12 21 10 15 26 40 36 48 44 45 41 52 45 46 37 42 38 37 36 24 25 23 23 27 15 22 18 10 9 0 11 12 11 4 16 5 2 6 3 4 5 2 7 7 1 3 1 0 1 2 2 4 3 0 0 1 0 0 0 0 1 1 1 0 0 1 0 0 0 0 1 0 0 0 0 1 0 1 0 0 0 2 0 0 1 0 0 0 0 0 0 0 0 0 0 2 0 0 0 0 2 0 0 0 0 0 0 0 0 1 0 0 0 0 0 0 0 0 0 1 0 0 0 0 0 0 0 0 2 0 0 0 0 0 0 0 0 1 2 0 0 0 0 0 0 0 2 3 0 0 0 0 1 0 0 0 0 1 1 0 0 0 0 0 1 0 1 0 0 0 0 0 0 0 1 0 0 0 0 1 0 0</intensities>
			</dataPoints>
		</scan>
		<scan appendNumber="0" mode="Continuous" scanAxis="2Theta" status="Completed">
			<header>
				<startTimeStamp>2016-06-23T14:48:13-07:00</startTimeStamp>
				<endTimeStamp>2016-06-23T14:48:21-07:00</endTimeStamp>
				<author>
					<name>user</name>
				</author>
				<source>
					<applicationSoftware version="4.2a">Data Collector</applicationSoftware>
					<instrumentControlSoftware version="2.1E 20110621">XPERT-PRO</instrumentControlSoftware>
					<instrumentID>0000000000030961</instrumentID>
				</source>
			</header>
			<scanAxisCenter>
				<position axis="2Theta" unit="deg">54.9088</position>
			</scanAxisCenter>
			<reflection>
				<material>Si [001]</material>
				<hkl>
					<h>-1</h>
					<k>-1</k>
					<l>3</l>
				</hkl>
				<unitCell>
					<alpha unit="deg">90.00000</alpha>
					<beta unit="deg">90.00000</beta>
					<gamma unit="deg">90.00000</gamma>
					<a unit="Angstrom">5.43119</a>
					<b unit="Angstrom">5.43119</b>
					<c unit="Angstrom">5.43119</c>
				</unitCell>
			</reflection>
			<dataPoints>
				<positions axis="2Theta" unit="deg">
					<startPosition>52.93924771</startPosition>
					<endPosition>56.87833249</endPosition>
				</positions>
				<positions axis="Omega" unit="deg">
					<commonPosition>51.5200</commonPosition>
				</positions>
				<positions axis="Phi" unit="deg">
					<commonPosition>0.00</commonPosition>
				</positions>
				<positions axis="Chi" unit="deg">
					<commonPosition>0.00</commonPosition>
				</positions>
				<positions axis="X" unit="mm">
					<commonPosition>0.00</commonPosition>
				</positions>
				<positions axis="Y" unit="mm">
					<commonPosition>0.00</commonPosition>
				</positions>
				<positions axis="Z" unit="mm">
					<commonPosition>8.075</commonPosition>
				</positions>
				<commonCountingTime unit="seconds">2.040</commonCountingTime>
				<intensities unit="counts">0 1 2 4 2 3 1 8 10 7 4 7 7 7 7 8 11 11 11 13 16 19 29 21 31 39 46 57 39 56 61 61 51 37 46 42 49 41 28 34 33 21 19 15 25 15 10 12 16 7 7 3 9 3 4 7 0 2 2 5 6 2 4 2 5 4 1 2 3 1 1 0 0 0 1 1 0 1 0 0 0 0 3 0 0 1 1 0 0 0 0 0 2 0 0 0 1 0 0 0 0 1 0 0 0 1 2 0 0 0 0 0 0 0 1 0 0 0 0 0 0 0 0 0 0 0 0 0 1 0 0 0 0 0 1 2 0 1 0 1 2 0 0 0 0 1 1 0 0 0 2 0 0 0 1 0 0 1 0 0 0 0 0 0 0 0 0 0 2 1 0 0 0 0 2 2 0 1 0 0 1 0 0 1 1 0 0 1 0 0 0 0 1 0 0 0 0 0 0 0 1</intensities>
			</dataPoints>
		</scan>
		<scan appendNumber="0" mode="Continuous" scanAxis="2Theta" status="Completed">
			<header>
				<startTimeStamp>2016-06-23T14:48:40-07:00</startTimeStamp>
				<endTimeStamp>2016-06-23T14:48:49-07:00</endTimeStamp>
				<author>
					<name>user</name>
				</author>
				<source>
					<applicationSoftware version="4.2a">Data Collector</applicationSoftware>
					<instrumentControlSoftware version="2.1E 20110621">XPERT-PRO</instrumentControlSoftware>
					<instrumentID>0000000000030961</instrumentID>
				</source>
			</header>
			<scanAxisCenter>
				<position axis="2Theta" unit="deg">54.9088</position>
			</scanAxisCenter>
			<reflection>
				<material>Si [001]</material>
				<hkl>
					<h>-1</h>
					<k>-1</k>
					<l>3</l>
				</hkl>
				<unitCell>
					<alpha unit="deg">90.00000</alpha>
					<beta unit="deg">90.00000</beta>
					<gamma unit="deg">90.00000</gamma>
					<a unit="Angstrom">5.43119</a>
					<b unit="Angstrom">5.43119</b>
					<c unit="Angstrom">5.43119</c>
				</unitCell>
			</reflection>
			<dataPoints>
				<positions axis="2Theta" unit="deg">
					<startPosition>52.93924771</startPosition>
					<endPosition>56.87833249</endPosition>
				</positions>
				<positions axis="Omega" unit="deg">
					<commonPosition>51.5400</commonPosition>
				</positions>
				<positions axis="Phi" unit="deg">
					<commonPosition>0.00</commonPosition>
				</positions>
				<positions axis="Chi" unit="deg">
					<commonPosition>0.00</commonPosition>
				</positions>
				<positions axis="X" unit="mm">
					<commonPosition>0.00</commonPosition>
				</positions>
				<positions axis="Y" unit="mm">
					<commonPosition>0.00</commonPosition>
				</positions>
				<positions axis="Z" unit="mm">
					<commonPosition>8.075</commonPosition>
				</positions>
				<commonCountingTime unit="seconds">2.040</commonCountingTime>
				<intensities unit="counts">0 1 3 3 1 0 8 7 4 10 11 6 6 6 8 6 10 15 13 12 16 25 25 23 47 39 32 50 54 54 61 52 61 47 59 62 54 38 40 44 33 29 26 13 16 23 16 9 14 10 18 6 2 13 2 10 6 0 7 2 1 5 3 1 1 2 2 1 0 0 0 0 1 1 0 1 0 5 1 0 1 2 1 1 1 0 0 1 0 3 0 1 0 0 0 1 0 0 1 0 1 0 0 0 0 0 0 0 0 1 0 2 2 0 0 0 0 0 0 0 0 0 0 0 0 1 0 0 0 0 0 1 0 0 2 0 1 3 1 0 0 0 0 0 0 0 0 0 0 1 0 1 0 0 1 0 2 1 1 0 0 4 3 0 1 0 0 0 0 0 1 0 0 0 0 0 0 0 2 2 0 0 0 2 0 0 0 0 0 0 0 0 0 0 0 0 0 0 0 0 0</intensities>
			</dataPoints>
		</scan>
		<scan appendNumber="0" mode="Continuous" scanAxis="2Theta" status="Completed">
			<header>
				<startTimeStamp>2016-06-23T14:49:03-07:00</startTimeStamp>
				<endTimeStamp>2016-06-23T14:49:11-07:00</endTimeStamp>
				<author>
					<name>user</name>
				</author>
				<source>
					<applicationSoftware version="4.2a">Data Collector</applicationSoftware>
					<instrumentControlSoftware version="2.1E 20110621">XPERT-PRO</instrumentControlSoftware>
					<instrumentID>0000000000030961</instrumentID>
				</source>
			</header>
			<scanAxisCenter>
				<position axis="2Theta" unit="deg">54.9088</position>
			</scanAxisCenter>
			<reflection>
				<material>Si [001]</material>
				<hkl>
					<h>-1</h>
					<k>-1</k>
					<l>3</l>
				</hkl>
				<unitCell>
					<alpha unit="deg">90.00000</alpha>
					<beta unit="deg">90.00000</beta>
					<gamma unit="deg">90.00000</gamma>
					<a unit="Angstrom">5.43119</a>
					<b unit="Angstrom">5.43119</b>
					<c unit="Angstrom">5.43119</c>
				</unitCell>
			</reflection>
			<dataPoints>
				<positions axis="2Theta" unit="deg">
					<startPosition>52.93924771</startPosition>
					<endPosition>56.87833249</endPosition>
				</positions>
				<positions axis="Omega" unit="deg">
					<commonPosition>51.5600</commonPosition>
				</positions>
				<positions axis="Phi" unit="deg">
					<commonPosition>0.00</commonPosition>
				</positions>
				<positions axis="Chi" unit="deg">
					<commonPosition>0.00</commonPosition>
				</positions>
				<positions axis="X" unit="mm">
					<commonPosition>0.00</commonPosition>
				</positions>
				<positions axis="Y" unit="mm">
					<commonPosition>0.00</commonPosition>
				</positions>
				<positions axis="Z" unit="mm">
					<commonPosition>8.075</commonPosition>
				</positions>
				<commonCountingTime unit="seconds">2.040</commonCountingTime>
				<intensities unit="counts">0 3 1 2 3 9 4 4 3 4 10 7 2 10 12 8 6 11 13 24 15 23 24 34 52 40 50 64 67 55 65 79 65 61 77 66 68 46 51 50 37 32 32 26 20 27 19 13 16 16 11 10 8 7 4 4 8 6 5 3 4 3 1 2 0 1 0 2 0 0 1 1 0 1 1 0 0 1 0 1 4 0 0 0 2 3 0 0 0 0 1 2 0 0 1 1 0 2 0 0 1 0 2 1 0 1 0 0 1 0 0 0 1 0 0 0 1 0 0 0 0 0 0 0 0 2 1 0 0 0 0 0 0 0 0 0 0 0 0 0 0 0 0 0 1 0 1 0 2 0 0 0 2 0 0 0 0 0 0 0 0 0 2 1 0 2 1 0 0 1 0 0 0 0 0 1 0 0 1 0 1 0 0 0 1 0 0 0 1 1 0 0 1 2 0 0 0 0 0 0 0</intensities>
			</dataPoints>
		</scan>
		<scan appendNumber="0" mode="Continuous" scanAxis="2Theta" status="Completed">
			<header>
				<startTimeStamp>2016-06-23T14:49:25-07:00</startTimeStamp>
				<endTimeStamp>2016-06-23T14:49:33-07:00</endTimeStamp>
				<author>
					<name>user</name>
				</author>
				<source>
					<applicationSoftware version="4.2a">Data Collector</applicationSoftware>
					<instrumentControlSoftware version="2.1E 20110621">XPERT-PRO</instrumentControlSoftware>
					<instrumentID>0000000000030961</instrumentID>
				</source>
			</header>
			<scanAxisCenter>
				<position axis="2Theta" unit="deg">54.9088</position>
			</scanAxisCenter>
			<reflection>
				<material>Si [001]</material>
				<hkl>
					<h>-1</h>
					<k>-1</k>
					<l>3</l>
				</hkl>
				<unitCell>
					<alpha unit="deg">90.00000</alpha>
					<beta unit="deg">90.00000</beta>
					<gamma unit="deg">90.00000</gamma>
					<a unit="Angstrom">5.43119</a>
					<b unit="Angstrom">5.43119</b>
					<c unit="Angstrom">5.43119</c>
				</unitCell>
			</reflection>
			<dataPoints>
				<positions axis="2Theta" unit="deg">
					<startPosition>52.93924771</startPosition>
					<endPosition>56.87833249</endPosition>
				</positions>
				<positions axis="Omega" unit="deg">
					<commonPosition>51.5800</commonPosition>
				</positions>
				<positions axis="Phi" unit="deg">
					<commonPosition>0.00</commonPosition>
				</positions>
				<positions axis="Chi" unit="deg">
					<commonPosition>0.00</commonPosition>
				</positions>
				<positions axis="X" unit="mm">
					<commonPosition>0.00</commonPosition>
				</positions>
				<positions axis="Y" unit="mm">
					<commonPosition>0.00</commonPosition>
[...]
					<gamma unit="deg">90.00000</gamma>
					<a unit="Angstrom">5.43119</a>
					<b unit="Angstrom">5.43119</b>
					<c unit="Angstrom">5.43119</c>
				</unitCell>
			</reflection>
			<dataPoints>
				<positions axis="2Theta" unit="deg">
					<startPosition>52.93924771</startPosition>
					<endPosition>56.87833249</endPosition>
				</positions>
				<positions axis="Omega" unit="deg">
					<commonPosition>54.0000</commonPosition>
				</positions>
				<positions axis="Phi" unit="deg">
					<commonPosition>0.00</commonPosition>
				</positions>
				<positions axis="Chi" unit="deg">
					<commonPosition>0.00</commonPosition>
				</positions>
				<positions axis="X" unit="mm">
					<commonPosition>0.00</commonPosition>
				</positions>
				<positions axis="Y" unit="mm">
					<commonPosition>0.00</commonPosition>
				</positions>
				<positions axis="Z" unit="mm">
					<commonPosition>8.075</commonPosition>
				</positions>
				<commonCountingTime unit="seconds">2.040</commonCountingTime>
				<intensities unit="counts">0 0 0 0 1 0 0 0 0 0 0 0 0 0 0 0 0 0 0 0 0 0 0 1 0 0 0 0 0 0 0 0 0 1 0 0 0 0 1 0 0 0 0 0 0 0 1 1 0 0 1 0 0 0 0 0 0 0 0 0 0 0 0 0 0 0 0 0 0 0 0 0 0 0 0 0 0 0 0 0 0 0 0 0 1 0 0 2 0 0 1 0 1 0 1 0 0 0 0 0 0 0 0 0 0 0 0 0 0 0 0 0 0 1 0 0 0 0 0 0 0 0 0 0 1 0 0 0 1 0 0 1 0 1 4 2 0 1 0 1 0 0 0 1 0 1 1 0 0 0 0 0 1 1 1 0 0 0 0 0 2 0 0 0 0 1 1 2 0 0 0 1 1 0 0 0 5 0 0 0 1 0 0 0 0 0 0 0 2 0 1 0 0 0 0 1 0 0 0 1 0</intensities>
			</dataPoints>
		</scan>
		<scan appendNumber="0" mode="Continuous" scanAxis="2Theta" status="Completed">
			<header>
				<startTimeStamp>2016-06-23T15:38:41-07:00</startTimeStamp>
				<endTimeStamp>2016-06-23T15:38:50-07:00</endTimeStamp>
				<author>
					<name>user</name>
				</author>
				<source>
					<applicationSoftware version="4.2a">Data Collector</applicationSoftware>
					<instrumentControlSoftware version="2.1E 20110621">XPERT-PRO</instrumentControlSoftware>
					<instrumentID>0000000000030961</instrumentID>
				</source>
			</header>
			<scanAxisCenter>
				<position axis="2Theta" unit="deg">54.9088</position>
			</scanAxisCenter>
			<reflection>
				<material>Si [001]</material>
				<hkl>
					<h>-1</h>
					<k>-1</k>
					<l>3</l>
				</hkl>
				<unitCell>
					<alpha unit="deg">90.00000</alpha>
					<beta unit="deg">90.00000</beta>
					<gamma unit="deg">90.00000</gamma>
					<a unit="Angstrom">5.43119</a>
					<b unit="Angstrom">5.43119</b>
					<c unit="Angstrom">5.43119</c>
				</unitCell>
			</reflection>
			<dataPoints>
				<positions axis="2Theta" unit="deg">
					<startPosition>52.93924771</startPosition>
					<endPosition>56.87833249</endPosition>
				</positions>
				<positions axis="Omega" unit="deg">
					<commonPosition>54.0200</commonPosition>
				</positions>
				<positions axis="Phi" unit="deg">
					<commonPosition>0.00</commonPosition>
				</positions>
				<positions axis="Chi" unit="deg">
					<commonPosition>0.00</commonPosition>
				</positions>
				<positions axis="X" unit="mm">
					<commonPosition>0.00</commonPosition>
				</positions>
				<positions axis="Y" unit="mm">
					<commonPosition>0.00</commonPosition>
				</positions>
				<positions axis="Z" unit="mm">
					<commonPosition>8.075</commonPosition>
				</positions>
				<commonCountingTime unit="seconds">2.040</commonCountingTime>
				<intensities unit="counts">0 0 0 0 0 0 0 0 0 0 0 1 0 0 0 0 0 0 0 0 0 0 0 0 0 1 0 0 0 0 0 0 0 0 0 0 0 0 0 0 0 1 0 0 0 0 0 0 0 0 0 0 0 0 0 0 0 0 0 0 0 0 0 0 0 0 0 1 0 0 0 0 0 0 1 0 0 1 0 1 0 0 1 0 3 0 1 0 0 1 0 0 0 0 0 0 0 1 0 0 0 1 0 0 0 1 0 0 0 0 0 0 0 1 0 0 0 1 1 0 1 0 0 1 0 1 1 1 2 1 0 0 0 0 0 0 0 0 0 1 0 0 0 0 0 0 0 0 2 0 0 0 3 2 1 0 0 0 3 1 0 0 0 1 0 0 1 0 0 0 0 1 0 0 1 0 1 0 1 1 3 0 1 0 0 1 0 0 1 0 1 1 2 0 0 0 0 0 0 0 1</intensities>
			</dataPoints>
		</scan>
		<scan appendNumber="0" mode="Continuous" scanAxis="2Theta" status="Completed">
			<header>
				<startTimeStamp>2016-06-23T15:39:06-07:00</startTimeStamp>
				<endTimeStamp>2016-06-23T15:39:15-07:00</endTimeStamp>
				<author>
					<name>user</name>
				</author>
				<source>
					<applicationSoftware version="4.2a">Data Collector</applicationSoftware>
					<instrumentControlSoftware version="2.1E 20110621">XPERT-PRO</instrumentControlSoftware>
					<instrumentID>0000000000030961</instrumentID>
				</source>
			</header>
			<scanAxisCenter>
				<position axis="2Theta" unit="deg">54.9088</position>
			</scanAxisCenter>
			<reflection>
				<material>Si [001]</material>
				<hkl>
					<h>-1</h>
					<k>-1</k>
					<l>3</l>
				</hkl>
				<unitCell>
					<alpha unit="deg">90.00000</alpha>
					<beta unit="deg">90.00000</beta>
					<gamma unit="deg">90.00000</gamma>
					<a unit="Angstrom">5.43119</a>
					<b unit="Angstrom">5.43119</b>
					<c unit="Angstrom">5.43119</c>
				</unitCell>
			</reflection>
			<dataPoints>
				<positions axis="2Theta" unit="deg">
					<startPosition>52.93924771</startPosition>
					<endPosition>56.87833249</endPosition>
				</positions>
				<positions axis="Omega" unit="deg">
					<commonPosition>54.0400</commonPosition>
				</positions>
				<positions axis="Phi" unit="deg">
					<commonPosition>0.00</commonPosition>
				</positions>
				<positions axis="Chi" unit="deg">
					<commonPosition>0.00</commonPosition>
				</positions>
				<positions axis="X" unit="mm">
					<commonPosition>0.00</commonPosition>
				</positions>
				<positions axis="Y" unit="mm">
					<commonPosition>0.00</commonPosition>
				</positions>
				<positions axis="Z" unit="mm">
					<commonPosition>8.075</commonPosition>
				</positions>
				<commonCountingTime unit="seconds">2.040</commonCountingTime>
				<intensities unit="counts">0 0 0 0 0 0 0 1 0 0 0 0 0 0 0 0 0 1 1 0 0 0 0 1 0 0 0 0 0 0 0 0 1 0 0 0 0 0 0 0 0 0 0 1 0 0 0 0 0 0 0 0 0 1 0 0 0 0 0 0 0 0 0 0 0 0 0 2 0 0 0 0 0 0 0 0 0 1 0 0 4 0 0 0 0 0 0 0 0 0 0 0 1 0 0 0 0 0 0 0 2 1 0 1 0 1 0 0 0 1 0 1 0 0 0 0 0 0 2 0 0 0 0 0 0 1 0 0 3 0 0 2 0 0 0 2 0 0 1 1 1 1 1 0 0 0 0 0 0 1 0 0 0 0 1 0 0 0 2 1 1 2 0 2 2 0 2 1 0 0 0 2 0 0 2 0 1 0 0 0 0 1 1 0 0 0 1 1 1 2 0 0 0 0 0 0 1 0 1 0 0</intensities>
			</dataPoints>
		</scan>
		<scan appendNumber="0" mode="Continuous" scanAxis="2Theta" status="Completed">
			<header>
				<startTimeStamp>2016-06-23T15:39:29-07:00</startTimeStamp>
				<endTimeStamp>2016-06-23T15:39:37-07:00</endTimeStamp>
				<author>
					<name>user</name>
				</author>
				<source>
					<applicationSoftware version="4.2a">Data Collector</applicationSoftware>
					<instrumentControlSoftware version="2.1E 20110621">XPERT-PRO</instrumentControlSoftware>
					<instrumentID>0000000000030961</instrumentID>
				</source>
			</header>
			<scanAxisCenter>
				<position axis="2Theta" unit="deg">54.9088</position>
			</scanAxisCenter>
			<reflection>
				<material>Si [001]</material>
				<hkl>
					<h>-1</h>
					<k>-1</k>
					<l>3</l>
				</hkl>
				<unitCell>
					<alpha unit="deg">90.00000</alpha>
					<beta unit="deg">90.00000</beta>
					<gamma unit="deg">90.00000</gamma>
					<a unit="Angstrom">5.43119</a>
					<b unit="Angstrom">5.43119</b>
					<c unit="Angstrom">5.43119</c>
				</unitCell>
			</reflection>
			<dataPoints>
				<positions axis="2Theta" unit="deg">
					<startPosition>52.93924771</startPosition>
					<endPosition>56.87833249</endPosition>
				</positions>
				<positions axis="Omega" unit="deg">
					<commonPosition>54.0600</commonPosition>
				</positions>
				<positions axis="Phi" unit="deg">
					<commonPosition>0.00</commonPosition>
				</positions>
				<positions axis="Chi" unit="deg">
					<commonPosition>0.00</commonPosition>
				</positions>
				<positions axis="X" unit="mm">
					<commonPosition>0.00</commonPosition>
				</positions>
				<positions axis="Y" unit="mm">
					<commonPosition>0.00</commonPosition>
				</positions>
				<positions axis="Z" unit="mm">
					<commonPosition>8.075</commonPosition>
				</positions>
				<commonCountingTime unit="seconds">2.040</commonCountingTime>
				<intensities unit="counts">0 0 0 0 0 0 0 0 0 0 1 0 1 0 0 0 0 0 0 0 0 0 0 0 0 0 1 0 0 0 1 1 0 0 0 0 0 0 1 1 0 0 0 0 0 0 0 0 0 0 0 0 0 0 0 0 0 0 0 1 0 1 0 0 0 0 1 0 0 0 0 0 0 0 0 0 0 1 0 0 0 1 3 1 0 0 0 0 0 0 0 1 0 0 1 0 0 1 0 1 0 1 0 0 0 0 0 0 0 0 0 0 0 0 0 1 0 1 0 0 2 0 0 0 0 0 1 1 0 1 0 0 0 0 0 0 0 1 0 0 1 0 0 0 0 0 1 0 0 1 0 1 0 0 1 0 0 0 0 0 0 0 2 2 1 0 1 0 1 0 3 0 0 0 0 0 1 3 1 0 0 0 1 0 1 0 0 0 1 1 1 1 0 1 0 0 0 0 2 0 0</intensities>
			</dataPoints>
		</scan>
		<scan appendNumber="0" mode="Continuous" scanAxis="2Theta" status="Completed">
			<header>
				<startTimeStamp>2016-06-23T15:39:49-07:00</startTimeStamp>
				<endTimeStamp>2016-06-23T15:39:58-07:00</endTimeStamp>
				<author>
					<name>user</name>
				</author>
				<source>
					<applicationSoftware version="4.2a">Data Collector</applicationSoftware>
					<instrumentControlSoftware version="2.1E 20110621">XPERT-PRO</instrumentControlSoftware>
					<instrumentID>0000000000030961</instrumentID>
				</source>
			</header>
			<scanAxisCenter>
				<position axis="2Theta" unit="deg">54.9088</position>
			</scanAxisCenter>
			<reflection>
				<material>Si [001]</material>
				<hkl>
					<h>-1</h>
					<k>-1</k>
					<l>3</l>
				</hkl>
				<unitCell>
					<alpha unit="deg">90.00000</alpha>
					<beta unit="deg">90.00000</beta>
					<gamma unit="deg">90.00000</gamma>
					<a unit="Angstrom">5.43119</a>
					<b unit="Angstrom">5.43119</b>
					<c unit="Angstrom">5.43119</c>
				</unitCell>
			</reflection>
			<dataPoints>
				<positions axis="2Theta" unit="deg">
					<startPosition>52.93924771</startPosition>
					<endPosition>56.87833249</endPosition>
				</positions>
				<positions axis="Omega" unit="deg">
					<commonPosition>54.0800</commonPosition>
				</positions>
				<positions axis="Phi" unit="deg">
					<commonPosition>0.00</commonPosition>
				</positions>
				<positions axis="Chi" unit="deg">
					<commonPosition>0.00</commonPosition>
				</positions>
				<positions axis="X" unit="mm">
					<commonPosition>0.00</commonPosition>
				</positions>
				<positions axis="Y" unit="mm">
					<commonPosition>0.00</commonPosition>
				</positions>
				<positions axis="Z" unit="mm">
					<commonPosition>8.075</commonPosition>
				</positions>
				<commonCountingTime unit="seconds">2.040</commonCountingTime>
				<intensities unit="counts">0 0 2 0 0 0 0 0 0 0 0 0 0 0 1 2 0 0 0 0 0 0 0 0 0 0 0 0 0 0 0 0 0 0 0 0 0 0 0 0 0 0 0 0 0 0 0 0 0 0 1 0 0 0 0 0 0 0 0 0 0 0 0 0 0 0 0 2 0 0 0 0 0 1 0 0 1 0 0 0 0 2 0 0 1 0 0 0 0 0 2 1 0 0 2 0 0 1 0 0 1 0 0 0 0 0 0 0 0 0 0 0 0 0 0 0 1 0 1 0 0 0 0 2 1 1 0 0 0 0 0 2 0 0 0 0 0 0 0 0 0 2 0 1 0 0 0 1 1 0 2 3 0 0 2 0 1 1 1 0 0 0 0 1 0 1 0 0 2 0 1 1 0 2 0 0 1 0 1 1 0 0 1 0 0 0 0 0 1 1 0 1 0 0 0 0 0 0 0 1 0</intensities>
			</dataPoints>
		</scan>
		<scan appendNumber="0" mode="Continuous" scanAxis="2Theta" status="Completed">
			<header>
				<startTimeStamp>2016-06-23T15:40:12-07:00</startTimeStamp>
				<endTimeStamp>2016-06-23T15:40:21-07:00</endTimeStamp>
				<author>
					<name>user</name>
				</author>
				<source>
					<applicationSoftware version="4.2a">Data Collector</applicationSoftware>
					<instrumentControlSoftware version="2.1E 20110621">XPERT-PRO</instrumentControlSoftware>
					<instrumentID>0000000000030961</instrumentID>
				</source>
			</header>
			<scanAxisCenter>
				<position axis="2Theta" unit="deg">54.9088</position>
			</scanAxisCenter>
			<reflection>
				<material>Si [001]</material>
				<hkl>
					<h>-1</h>
					<k>-1</k>
					<l>3</l>
				</hkl>
				<unitCell>
					<alpha unit="deg">90.00000</alpha>
					<beta unit="deg">90.00000</beta>
					<gamma unit="deg">90.00000</gamma>
					<a unit="Angstrom">5.43119</a>
					<b unit="Angstrom">5.43119</b>
					<c unit="Angstrom">5.43119</c>
				</unitCell>
			</reflection>
			<dataPoints>
				<positions axis="2Theta" unit="deg">
					<startPosition>52.93924771</startPosition>
					<endPosition>56.87833249</endPosition>
				</positions>
				<positions axis="Omega" unit="deg">
					<commonPosition>54.1000</commonPosition>
				</positions>
				<positions axis="Phi" unit="deg">
					<commonPosition>0.00</commonPosition>
				</positions>
				<positions axis="Chi" unit="deg">
					<commonPosition>0.00</commonPosition>
				</positions>
				<positions axis="X" unit="mm">
					<commonPosition>0.00</commonPosition>
				</positions>
				<positions axis="Y" unit="mm">
					<commonPosition>0.00</commonPosition>
				</positions>
				<positions axis="Z" unit="mm">
					<commonPosition>8.075</commonPosition>
				</positions>
				<commonCountingTime unit="seconds">2.040</commonCountingTime>
				<intensities unit="counts">0 0 0 0 0 0 0 0 0 0 0 0 0 1 0 0 0 0 0 0 0 0 0 0 0 0 0 0 0 0 2 0 0 0 0 0 0 1 0 0 0 0 0 0 0 0 0 0 0 0 0 0 1 0 0 0 0 0 0 0 0 0 2 0 0 0 0 0 0 0 1 0 0 0 1 0 0 1 0 0 0 0 0 0 1 0 0 0 2 1 0 0 1 1 0 0 0 0 0 0 0 0 0 2 0 0 0 0 1 0 0 0 0 0 0 0 0 0 2 0 0 1 0 0 0 1 0 0 0 0 0 0 0 2 0 0 0 0 0 1 0 0 0 1 0 1 0 0 0 0 1 0 1 0 1 0 0 2 0 2 0 1 0 0 0 0 1 0 1 1 2 0 0 0 0 0 0 0 0 0 0 1 1 1 0 0 1 1 0 0 4 0 0 0 0 2 0 0 0 0 1</intensities>
			</dataPoints>
		</scan>
		<scan appendNumber="0" mode="Continuous" scanAxis="2Theta" status="Completed">
			<header>
				<startTimeStamp>2016-06-23T15:40:39-07:00</startTimeStamp>
				<endTimeStamp>2016-06-23T15:40:47-07:00</endTimeStamp>
				<author>
					<name>user</name>
				</author>
				<source>
					<applicationSoftware version="4.2a">Data Collector</applicationSoftware>
					<instrumentControlSoftware version="2.1E 20110621">XPERT-PRO</instrumentControlSoftware>
					<instrumentID>0000000000030961</instrumentID>
				</source>
			</header>
			<scanAxisCenter>
				<position axis="2Theta" unit="deg">54.9088</position>
			</scanAxisCenter>
			<reflection>
				<material>Si [001]</material>
				<hkl>
					<h>-1</h>
					<k>-1</k>
					<l>3</l>
				</hkl>
				<unitCell>
					<alpha unit="deg">90.00000</alpha>
					<beta unit="deg">90.00000</beta>
					<gamma unit="deg">90.00000</gamma>
					<a unit="Angstrom">5.43119</a>
					<b unit="Angstrom">5.43119</b>
					<c unit="Angstrom">5.43119</c>
				</unitCell>
			</reflection>
			<dataPoints>
				<positions axis="2Theta" unit="deg">
					<startPosition>52.93924771</startPosition>
					<endPosition>56.87833249</endPosition>
				</positions>
				<positions axis="Omega" unit="deg">
					<commonPosition>54.1200</commonPosition>
				</positions>
				<positions axis="Phi" unit="deg">
					<commonPosition>0.00</commonPosition>
				</positions>
				<positions axis="Chi" unit="deg">
					<commonPosition>0.00</commonPosition>
				</positions>
				<positions axis="X" unit="mm">
					<commonPosition>0.00</commonPosition>
				</positions>
				<positions axis="Y" unit="mm">
					<commonPosition>0.00</commonPosition>
				</positions>
				<positions axis="Z" unit="mm">
					<commonPosition>8.075</commonPosition>
				</positions>
				<commonCountingTime unit="seconds">2.040</commonCountingTime>
				<intensities unit="counts">0 0 0 0 1 0 0 0 0 0 0 0 0 0 0 0 0 0 0 0 0 1 0 0 0 0 0 0 0 0 0 0 1 0 0 0 0 1 0 0 1 0 0 0 0 0 0 0 1 0 0 0 0 0 0 0 0 0 0 0 0 0 0 0 1 0 0 0 0 0 0 0 1 0 0 0 0 0 0 0 0 0 0 0 0 1 0 1 0 0 0 0 0 0 0 3 0 0 0 0 0 0 0 0 0 0 0 0 0 0 0 0 0 0 0 0 0 1 0 0 0 0 1 0 0 0 0 2 0 0 0 1 0 0 1 0 0 0 0 0 0 0 1 2 0 0 0 0 1 1 1 0 0 0 0 0 0 0 0 1 1 0 0 0 0 0 3 0 0 0 1 0 0 0 0 0 1 0 1 4 3 0 0 0 1 1 2 0 0 0 4 0 1 1 1 0 0 0 1 0 1</intensities>
			</dataPoints>
		</scan>
		<scan appendNumber="0" mode="Continuous" scanAxis="2Theta" status="Completed">
			<header>
				<startTimeStamp>2016-06-23T15:41:10-07:00</startTimeStamp>
				<endTimeStamp>2016-06-23T15:41:18-07:00</endTimeStamp>
				<author>
					<name>user</name>
				</author>
				<source>
					<applicationSoftware version="4.2a">Data Collector</applicationSoftware>
					<instrumentControlSoftware version="2.1E 20110621">XPERT-PRO</instrumentControlSoftware>
					<instrumentID>0000000000030961</instrumentID>
				</source>
			</header>
			<scanAxisCenter>
				<position axis="2Theta" unit="deg">54.9088</position>
			</scanAxisCenter>
			<reflection>
				<material>Si [001]</material>
				<hkl>
					<h>-1</h>
					<k>-1</k>
					<l>3</l>
				</hkl>
				<unitCell>
					<alpha unit="deg">90.00000</alpha>
					<beta unit="deg">90.00000</beta>
					<gamma unit="deg">90.00000</gamma>
					<a unit="Angstrom">5.43119</a>
					<b unit="Angstrom">5.43119</b>
					<c unit="Angstrom">5.43119</c>
				</unitCell>
			</reflection>
			<dataPoints>
				<positions axis="2Theta" unit="deg">
					<startPosition>52.93924771</startPosition>
					<endPosition>56.87833249</endPosition>
				</positions>
				<positions axis="Omega" unit="deg">
					<commonPosition>54.1400</commonPosition>
				</positions>
				<positions axis="Phi" unit="deg">
					<commonPosition>0.00</commonPosition>
				</positions>
				<positions axis="Chi" unit="deg">
					<commonPosition>0.00</commonPosition>
				</positions>
				<positions axis="X" unit="mm">
					<commonPosition>0.00</commonPosition>
				</positions>
				<positions axis="Y" unit="mm">
					<commonPosition>0.00</commonPosition>
				</positions>
				<positions axis="Z" unit="mm">
					<commonPosition>8.075</commonPosition>
				</positions>
				<commonCountingTime unit="seconds">2.040</commonCountingTime>
				<intensities unit="counts">0 0 0 0 0 0 0 0 0 0 0 0 0 0 0 0 1 0 0 1 0 0 0 0 0 0 0 0 1 0 2 0 0 0 0 0 0 0 1 0 0 0 0 0 0 0 0 0 0 0 0 0 0 2 0 0 0 0 0 0 0 0 0 0 0 0 1 0 0 0 0 0 0 0 0 0 0 0 0 0 0 0 1 0 0 0 0 0 1 0 0 0 0 0 0 0 0 0 0 0 0 0 0 0 0 0 0 0 0 0 0 0 0 1 2 1 0 0 0 0 1 0 0 0 1 3 0 0 0 0 0 0 1 2 0 0 0 1 0 0 0 0 0 0 0 0 0 0 1 0 1 1 0 0 0 2 0 1 0 0 3 0 0 1 1 0 2 0 1 1 0 1 0 0 0 0 1 1 0 0 0 0 1 0 1 0 1 0 1 1 0 0 0 0 0 0 1 2 0 0 0</intensities>
			</dataPoints>
		</scan>
		<scan appendNumber="0" mode="Continuous" scanAxis="2Theta" status="Completed">
			<header>
				<startTimeStamp>2016-06-23T15:41:33-07:00</startTimeStamp>
				<endTimeStamp>2016-06-23T15:41:42-07:00</endTimeStamp>
				<author>
					<name>user</name>
				</author>
				<source>
					<applicationSoftware version="4.2a">Data Collector</applicationSoftware>
					<instrumentControlSoftware version="2.1E 20110621">XPERT-PRO</instrumentControlSoftware>
					<instrumentID>0000000000030961</instrumentID>
				</source>
			</header>
			<scanAxisCenter>
				<position axis="2Theta" unit="deg">54.9088</position>
			</scanAxisCenter>
			<reflection>
				<material>Si [001]</material>
				<hkl>
					<h>-1</h>
					<k>-1</k>
					<l>3</l>
				</hkl>
				<unitCell>
					<alpha unit="deg">90.00000</alpha>
					<beta unit="deg">90.00000</beta>
					<gamma unit="deg">90.00000</gamma>
					<a unit="Angstrom">5.43119</a>
					<b unit="Angstrom">5.43119</b>
					<c unit="Angstrom">5.43119</c>
				</unitCell>
			</reflection>
			<dataPoints>
				<positions axis="2Theta" unit="deg">
					<startPosition>52.93924771</startPosition>
					<endPosition>56.87833249</endPosition>
				</positions>
				<positions axis="Omega" unit="deg">
					<commonPosition>54.1600</commonPosition>
				</positions>
				<positions axis="Phi" unit="deg">
					<commonPosition>0.00</commonPosition>
				</positions>
				<positions axis="Chi" unit="deg">
					<commonPosition>0.00</commonPosition>
				</positions>
				<positions axis="X" unit="mm">
					<commonPosition>0.00</commonPosition>
				</positions>
				<positions axis="Y" unit="mm">
					<commonPosition>0.00</commonPosition>
				</positions>
				<positions axis="Z" unit="mm">
					<commonPosition>8.075</commonPosition>
				</positions>
				<commonCountingTime unit="seconds">2.040</commonCountingTime>
				<intensities unit="counts">0 0 0 0 0 0 0 0 1 0 0 0 0 0 0 0 0 0 0 0 0 1 0 0 0 0 0 0 0 0 0 0 0 0 0 0 0 0 1 0 0 0 0 0 0 0 1 0 0 0 0 0 0 0 0 1 0 0 0 0 0 0 0 0 0 0 0 0 0 0 0 0 0 0 0 0 0 0 0 0 0 0 0 2 0 0 0 0 1 0 0 1 0 0 0 0 0 0 0 0 0 0 0 2 0 2 0 2 0 0 0 0 0 0 0 0 0 0 0 0 0 0 0 0 0 0 1 1 0 0 1 0 1 0 1 0 0 0 0 0 1 0 0 0 1 0 0 0 0 1 0 0 1 0 0 0 1 0 1 1 1 0 2 1 0 1 1 0 0 1 0 0 1 1 0 0 0 1 0 0 0 2 0 0 2 0 2 0 1 0 0 0 0 0 0 0 0 1 0 0 1</intensities>
			</dataPoints>
		</scan>
	</xrdMeasurement>
</xrdMeasurements>