File: ReciprocalSpaceMapAnalysis/Reciprocal Space Working/RLM_01_1.xrdml
<?xml version="1.0" encoding="UTF-8"?>
<xrdMeasurements xmlns="http://www.xrdml.com/XRDMeasurement/1.5" xmlns:xsi="http://www.w3.org/2001/XMLSchema-instance" xsi:schemaLocation="http://www.xrdml.com/XRDMeasurement/1.5 http://www.xrdml.com/XRDMeasurement/1.5/XRDMeasurement.xsd" status="Aborted">
	<comment>
		<entry>Configuration=Hybrid + RC/Triple, Owner=Arturas, Creation date=11/27/2001 11:15:26 PM</entry>
		<entry>Goniometer=PW3050/65 (Theta/2Theta); Minimum step size 2Theta:0.0001; Minimum step size Omega:0.0001</entry>
		<entry>Sample stage=MRD Cradle; Minimum step size Phi:0.01; Minimum step size Chi:0.01; Minimum step size X:0.01; Minimum step size Y:0.01; Minimum step size Z:0.001</entry>
		<entry>Diffractometer system=XPERT-PRO</entry>
		<entry>Measurement program=C:\XPERT1_USERS\mbraun7\RLM_01.xrdmp, Identifier={0F21CDFD-19CE-484D-9892-0BCC9C1E997B}</entry>
	</comment>
	<sample type="To be analyzed">
		<id></id>
		<name></name>
		<preparedBy></preparedBy>
	</sample>
	<xrdMeasurement measurementType="Area measurement" status="Aborted" measurementStepAxis="Omega" sampleMode="Reflection">
		<comment>
			<entry/>
		</comment>
		<usedWavelength intended="K-Alpha 1">
			<kAlpha1 unit="Angstrom">1.5405980</kAlpha1>
			<kAlpha2 unit="Angstrom">1.5444260</kAlpha2>
			<kBeta unit="Angstrom">1.3922500</kBeta>
			<ratioKAlpha2KAlpha1>0.0000</ratioKAlpha2KAlpha1>
		</usedWavelength>
		<incidentBeamPath>
			<radius unit="mm">320.00</radius>
			<xRayTube id="1010048" name="Empyrean Cu LFF HR (9430 033 7310x) DK347677">
				<tension unit="kV">45</tension>
				<current unit="mA">40</current>
				<anodeMaterial>Cu</anodeMaterial>
				<focus type="Line">
					<length unit="mm">12.0</length>
					<width unit="mm">0.4</width>
					<takeOffAngle unit="deg">2.5</takeOffAngle>
				</focus>
			</xRayTube>
			<xRayMirror id="27090001" name="Inc. Beam Cu W/Si (hybrid MRD)" hybrid="true">
				<crystal type="Graded" shape="Parabolic">W/Si</crystal>
				<acceptanceAngle unit="deg">0.800</acceptanceAngle>
				<length unit="mm">60.0</length>
			</xRayMirror>
			<monochromator id="23090001" name="Hybrid monochr. 4xGe(220) for Cu" hybrid="true">
				<crystal type="Symmetric" shape="Flat">Ge</crystal>
				<numberOfReflections>4</numberOfReflections>
				<hkl>
					<h>2</h>
					<k>2</k>
					<l>0</l>
				</hkl>
			</monochromator>
			<mask id="22080004" name="Fixed incident beam mask 20 mm">
				<distanceToSample unit="mm">220.00</distanceToSample>
				<width unit="mm">17.20</width>
			</mask>
			<divergenceSlit id="22010004" name="Fixed slit 1/2Â°" xsi:type="fixedDivergenceSlitType">
				<distanceToSample unit="mm">220.00</distanceToSample>
				<height unit="mm">0.76</height>
			</divergenceSlit>
			<beamAttenuator id="26010001" name="Progr. beam attenuator Ni 0.125 mm" xsi:type="intensitySwitchedBeamAttenuatorType">
				<factor>148.12</factor>
				<material>Ni</material>
				<activateLevel unit="counts per second">500000</activateLevel>
				<deactivateLevel unit="counts per second">450000</deactivateLevel>
			</beamAttenuator>
		</incidentBeamPath>
		<sampleOffset>
			<position axis="2Theta" unit="deg">-0.0523</position>
			<position axis="Omega" unit="deg">0.0853</position>
			<position axis="Phi" unit="deg">-5.15</position>
			<position axis="Chi" unit="deg">0.11</position>
		</sampleOffset>
		<diffractedBeamPath>
			<radius unit="mm">320.00</radius>
			<monochromator id="23010018" name="3xGe(220) symmetrical analyzer for Cu" hybrid="false">
				<crystal type="Symmetric" shape="Flat">Ge</crystal>
				<numberOfReflections>3</numberOfReflections>
				<hkl>
					<h>2</h>
					<k>2</k>
					<l>0</l>
				</hkl>
			</monochromator>
			<detector id="7010011" name="Proportional detector Xe" xsi:type="pointDetectorType">
				<phd>
					<lowerLevel unit="%">35.0</lowerLevel>
					<upperLevel unit="%">80.0</upperLevel>
				</phd>
			</detector>
		</diffractedBeamPath>
		<measurementStepAxisCenter>
			<position axis="Omega" unit="deg">7.7889</position>
		</measurementStepAxisCenter>
		<scan appendNumber="0" mode="Continuous" scanAxis="Omega-2Theta" status="Completed">
			<header>
				<startTimeStamp>2016-02-08T09:53:23-08:00</startTimeStamp>
				<endTimeStamp>2016-02-08T09:54:47-08:00</endTimeStamp>
				<author>
					<name>user</name>
				</author>
				<source>
					<applicationSoftware version="4.2a">Data Collector</applicationSoftware>
					<instrumentControlSoftware version="2.2  20130918">XPERT-PRO</instrumentControlSoftware>
					<instrumentID>0000000013085222</instrumentID>
				</source>
			</header>
			<scanAxisCenter>
				<position axis="2Theta" unit="deg">86.8399</position>
				<position axis="Omega" unit="deg">6.9864</position>
			</scanAxisCenter>
			<reflection>
				<material>Si [001]</material>
				<hkl>
					<h>2</h>
					<k>2</k>
					<l>4</l>
				</hkl>
				<unitCell>
					<alpha unit="deg">90.00000</alpha>
					<beta unit="deg">90.00000</beta>
					<gamma unit="deg">90.00000</gamma>
					<a unit="Angstrom">5.43119</a>
					<b unit="Angstrom">5.43119</b>
					<c unit="Angstrom">5.43119</c>
				</unitCell>
			</reflection>
			<dataPoints>
				<positions axis="2Theta" unit="deg">
					<startPosition>84.9800</startPosition>
					<endPosition>88.7000</endPosition>
				</positions>
				<positions axis="Omega" unit="deg">
					<startPosition>6.0564</startPosition>
					<endPosition>7.9164</endPosition>
				</positions>
				<positions axis="Phi" unit="deg">
					<commonPosition>0.00</commonPosition>
				</positions>
				<positions axis="Chi" unit="deg">
					<commonPosition>0.00</commonPosition>
				</positions>
				<positions axis="X" unit="mm">
					<commonPosition>0.00</commonPosition>
				</positions>
				<positions axis="Y" unit="mm">
					<commonPosition>0.00</commonPosition>
				</positions>
				<positions axis="Z" unit="mm">
					<commonPosition>8.416</commonPosition>
				</positions>
				<beamAttenuationFactors>1.00 1.00 1.00 1.00 1.00 1.00 1.00 1.00 1.00 1.00 1.00 1.00 1.00 1.00 1.00 1.00 1.00 1.00 1.00 1.00 1.00 1.00 1.00 1.00 1.00 1.00 1.00 1.00 1.00 1.00 1.00 1.00 1.00 1.00 1.00 1.00 1.00 1.00 1.00 1.00 1.00 1.00 1.00 1.00 1.00 1.00 1.00 1.00 1.00 1.00 1.00 1.00 1.00 1.00 1.00 1.00 1.00 1.00 1.00 1.00 1.00 1.00 1.00 1.00 1.00 1.00 1.00 1.00 1.00 1.00 1.00 1.00 1.00 1.00 1.00 1.00 1.00 1.00 1.00 1.00 1.00 1.00 1.00 1.00 1.00 1.00 1.00 1.00 1.00 1.00 1.00 1.00 1.00 1.00 1.00 1.00 1.00 1.00 1.00 1.00 1.00 1.00 1.00 1.00 1.00 1.00 1.00 1.00 1.00 1.00 1.00 1.00 1.00 1.00 1.00 1.00 1.00 1.00 1.00 1.00 1.00 1.00 1.00 1.00 1.00</beamAttenuationFactors>
				<commonCountingTime unit="seconds">0.50</commonCountingTime>
				<intensities unit="counts">0 0 1 0 0 0 0 0 1 0 1 0 0 1 2 1 1 0 0 0 0 1 0 0 1 1 0 0 0 0 0 0 0 0 1 1 0 1 1 1 1 1 1 0 2 0 0 1 0 0 2 1 0 1 0 0 0 1 0 1 0 0 0 1 0 0 0 1 0 0 0 0 0 1 1 0 2 0 0 0 1 0 0 0 1 0 2 0 2 0 0 0 1 0 0 3 1 0 1 1 0 0 0 0 0 0 1 1 0 1 0 0 0 0 1 0 2 0 1 1 0 0 0 1 0</intensities>
			</dataPoints>
		</scan>
		<scan appendNumber="0" mode="Continuous" scanAxis="Omega-2Theta" status="Completed">
			<header>
				<startTimeStamp>2016-02-08T09:55:02-08:00</startTimeStamp>
				<endTimeStamp>2016-02-08T09:56:26-08:00</endTimeStamp>
				<author>
					<name>user</name>
				</author>
				<source>
					<applicationSoftware version="4.2a">Data Collector</applicationSoftware>
					<instrumentControlSoftware version="2.2  20130918">XPERT-PRO</instrumentControlSoftware>
					<instrumentID>0000000013085222</instrumentID>
				</source>
			</header>
			<scanAxisCenter>
				<position axis="2Theta" unit="deg">86.8400</position>
				<position axis="Omega" unit="deg">7.0014</position>
			</scanAxisCenter>
			<reflection>
				<material>Si [001]</material>
				<hkl>
					<h>2</h>
					<k>2</k>
					<l>4</l>
				</hkl>
				<unitCell>
					<alpha unit="deg">90.00000</alpha>
					<beta unit="deg">90.00000</beta>
					<gamma unit="deg">90.00000</gamma>
					<a unit="Angstrom">5.43119</a>
					<b unit="Angstrom">5.43119</b>
					<c unit="Angstrom">5.43119</c>
				</unitCell>
			</reflection>
			<dataPoints>
				<positions axis="2Theta" unit="deg">
					<startPosition>84.9800</startPosition>
					<endPosition>88.7000</endPosition>
				</positions>
				<positions axis="Omega" unit="deg">
					<startPosition>6.0714</startPosition>
					<endPosition>7.9314</endPosition>
				</positions>
				<positions axis="Phi" unit="deg">
					<commonPosition>0.00</commonPosition>
				</positions>
				<positions axis="Chi" unit="deg">
					<commonPosition>0.00</commonPosition>
				</positions>
				<positions axis="X" unit="mm">
					<commonPosition>0.00</commonPosition>
				</positions>
				<positions axis="Y" unit="mm">
					<commonPosition>0.00</commonPosition>
				</positions>
				<positions axis="Z" unit="mm">
					<commonPosition>8.416</commonPosition>
				</positions>
				<beamAttenuationFactors>1.00 1.00 1.00 1.00 1.00 1.00 1.00 1.00 1.00 1.00 1.00 1.00 1.00 1.00 1.00 1.00 1.00 1.00 1.00 1.00 1.00 1.00 1.00 1.00 1.00 1.00 1.00 1.00 1.00 1.00 1.00 1.00 1.00 1.00 1.00 1.00 1.00 1.00 1.00 1.00 1.00 1.00 1.00 1.00 1.00 1.00 1.00 1.00 1.00 1.00 1.00 1.00 1.00 1.00 1.00 1.00 1.00 1.00 1.00 1.00 1.00 1.00 1.00 1.00 1.00 1.00 1.00 1.00 1.00 1.00 1.00 1.00 1.00 1.00 1.00 1.00 1.00 1.00 1.00 1.00 1.00 1.00 1.00 1.00 1.00 1.00 1.00 1.00 1.00 1.00 1.00 1.00 1.00 1.00 1.00 1.00 1.00 1.00 1.00 1.00 1.00 1.00 1.00 1.00 1.00 1.00 1.00 1.00 1.00 1.00 1.00 1.00 1.00 1.00 1.00 1.00 1.00 1.00 1.00 1.00 1.00 1.00 1.00 1.00 1.00</beamAttenuationFactors>
				<commonCountingTime unit="seconds">0.50</commonCountingTime>
				<intensities unit="counts">0 1 0 0 0 1 0 0 2 0 1 1 1 0 0 0 2 0 0 0 1 0 0 0 1 0 0 0 0 0 0 0 1 0 0 0 1 1 2 0 0 1 1 0 0 0 2 1 1 0 0 0 0 0 0 0 0 1 0 1 0 1 2 0 0 1 0 0 0 0 0 0 0 0 1 2 0 0 0 0 0 0 0 0 0 1 0 0 0 1 0 0 4 0 0 0 1 0 0 0 0 1 0 0 0 0 0 0 0 0 1 0 0 0 0 0 1 0 0 0 0 0 0 0 0</intensities>
			</dataPoints>
		</scan>
		<scan appendNumber="0" mode="Continuous" scanAxis="Omega-2Theta" status="Completed">
			<header>
				<startTimeStamp>2016-02-08T09:56:41-08:00</startTimeStamp>
				<endTimeStamp>2016-02-08T09:58:05-08:00</endTimeStamp>
				<author>
					<name>user</name>
				</author>
				<source>
					<applicationSoftware version="4.2a">Data Collector</applicationSoftware>
					<instrumentControlSoftware version="2.2  20130918">XPERT-PRO</instrumentControlSoftware>
					<instrumentID>0000000013085222</instrumentID>
				</source>
			</header>
			<scanAxisCenter>
				<position axis="2Theta" unit="deg">86.8400</position>
				<position axis="Omega" unit="deg">7.0164</position>
			</scanAxisCenter>
			<reflection>
				<material>Si [001]</material>
				<hkl>
					<h>2</h>
					<k>2</k>
					<l>4</l>
				</hkl>
				<unitCell>
					<alpha unit="deg">90.00000</alpha>
					<beta unit="deg">90.00000</beta>
					<gamma unit="deg">90.00000</gamma>
					<a unit="Angstrom">5.43119</a>
					<b unit="Angstrom">5.43119</b>
					<c unit="Angstrom">5.43119</c>
				</unitCell>
			</reflection>
			<dataPoints>
				<positions axis="2Theta" unit="deg">
					<startPosition>84.9800</startPosition>
					<endPosition>88.7000</endPosition>
				</positions>
				<positions axis="Omega" unit="deg">
					<startPosition>6.0864</startPosition>
					<endPosition>7.9464</endPosition>
				</positions>
				<positions axis="Phi" unit="deg">
					<commonPosition>0.00</commonPosition>
				</positions>
				<positions axis="Chi" unit="deg">
					<commonPosition>0.00</commonPosition>
				</positions>
				<positions axis="X" unit="mm">
					<commonPosition>0.00</commonPosition>
				</positions>
				<positions axis="Y" unit="mm">
					<commonPosition>0.00</commonPosition>
				</positions>
				<positions axis="Z" unit="mm">
					<commonPosition>8.416</commonPosition>
				</positions>
				<beamAttenuationFactors>1.00 1.00 1.00 1.00 1.00 1.00 1.00 1.00 1.00 1.00 1.00 1.00 1.00 1.00 1.00 1.00 1.00 1.00 1.00 1.00 1.00 1.00 1.00 1.00 1.00 1.00 1.00 1.00 1.00 1.00 1.00 1.00 1.00 1.00 1.00 1.00 1.00 1.00 1.00 1.00 1.00 1.00 1.00 1.00 1.00 1.00 1.00 1.00 1.00 1.00 1.00 1.00 1.00 1.00 1.00 1.00 1.00 1.00 1.00 1.00 1.00 1.00 1.00 1.00 1.00 1.00 1.00 1.00 1.00 1.00 1.00 1.00 1.00 1.00 1.00 1.00 1.00 1.00 1.00 1.00 1.00 1.00 1.00 1.00 1.00 1.00 1.00 1.00 1.00 1.00 1.00 1.00 1.00 1.00 1.00 1.00 1.00 1.00 1.00 1.00 1.00 1.00 1.00 1.00 1.00 1.00 1.00 1.00 1.00 1.00 1.00 1.00 1.00 1.00 1.00 1.00 1.00 1.00 1.00 1.00 1.00 1.00 1.00 1.00 1.00</beamAttenuationFactors>
				<commonCountingTime unit="seconds">0.50</commonCountingTime>
				<intensities unit="counts">1 0 0 0 0 1 0 0 1 0 0 0 0 1 0 0 0 0 1 2 0 0 0 0 0 0 1 0 0 2 0 0 0 2 0 0 0 0 0 1 0 1 1 0 0 1 0 0 1 0 0 0 0 0 2 1 0 0 0 1 0 0 0 0 1 0 1 1 0 1 0 1 0 0 0 0 1 0 0 4 2 1 0 1 1 0 2 0 0 0 0 0 2 0 0 0 1 0 1 0 1 1 0 1 1 0 0 2 1 0 1 1 0 0 1 1 0 0 0 0 0 0 0 0 1</intensities>
			</dataPoints>
		</scan>
		<scan appendNumber="0" mode="Continuous" scanAxis="Omega-2Theta" status="Completed">
			<header>
				<startTimeStamp>2016-02-08T09:58:19-08:00</startTimeStamp>
				<endTimeStamp>2016-02-08T09:59:43-08:00</endTimeStamp>
				<author>
					<name>user</name>
				</author>
				<source>
					<applicationSoftware version="4.2a">Data Collector</applicationSoftware>
					<instrumentControlSoftware version="2.2  20130918">XPERT-PRO</instrumentControlSoftware>
					<instrumentID>0000000013085222</instrumentID>
				</source>
			</header>
			<scanAxisCenter>
				<position axis="2Theta" unit="deg">86.8400</position>
				<position axis="Omega" unit="deg">7.0314</position>
			</scanAxisCenter>
			<reflection>
				<material>Si [001]</material>
				<hkl>
					<h>2</h>
					<k>2</k>
					<l>4</l>
				</hkl>
				<unitCell>
					<alpha unit="deg">90.00000</alpha>
					<beta unit="deg">90.00000</beta>
					<gamma unit="deg">90.00000</gamma>
					<a unit="Angstrom">5.43119</a>
					<b unit="Angstrom">5.43119</b>
					<c unit="Angstrom">5.43119</c>
				</unitCell>
			</reflection>
			<dataPoints>
				<positions axis="2Theta" unit="deg">
					<startPosition>84.9800</startPosition>
					<endPosition>88.7000</endPosition>
				</positions>
				<positions axis="Omega" unit="deg">
					<startPosition>6.1014</startPosition>
					<endPosition>7.9614</endPosition>
				</positions>
				<positions axis="Phi" unit="deg">
					<commonPosition>0.00</commonPosition>
				</positions>
				<positions axis="Chi" unit="deg">
					<commonPosition>0.00</commonPosition>
				</positions>
				<positions axis="X" unit="mm">
					<commonPosition>0.00</commonPosition>
				</positions>
				<positions axis="Y" unit="mm">
					<commonPosition>0.00</commonPosition>
				</positions>
				<positions axis="Z" unit="mm">
					<commonPosition>8.416</commonPosition>
				</positions>
				<beamAttenuationFactors>1.00 1.00 1.00 1.00 1.00 1.00 1.00 1.00 1.00 1.00 1.00 1.00 1.00 1.00 1.00 1.00 1.00 1.00 1.00 1.00 1.00 1.00 1.00 1.00 1.00 1.00 1.00 1.00 1.00 1.00 1.00 1.00 1.00 1.00 1.00 1.00 1.00 1.00 1.00 1.00 1.00 1.00 1.00 1.00 1.00 1.00 1.00 1.00 1.00 1.00 1.00 1.00 1.00 1.00 1.00 1.00 1.00 1.00 1.00 1.00 1.00 1.00 1.00 1.00 1.00 1.00 1.00 1.00 1.00 1.00 1.00 1.00 1.00 1.00 1.00 1.00 1.00 1.00 1.00 1.00 1.00 1.00 1.00 1.00 1.00 1.00 1.00 1.00 1.00 1.00 1.00 1.00 1.00 1.00 1.00 1.00 1.00 1.00 1.00 1.00 1.00 1.00 1.00 1.00 1.00 1.00 1.00 1.00 1.00 1.00 1.00 1.00 1.00 1.00 1.00 1.00 1.00 1.00 1.00 1.00 1.00 1.00 1.00 1.00 1.00</beamAttenuationFactors>
				<commonCountingTime unit="seconds">0.50</commonCountingTime>
				<intensities unit="counts">0 0 0 0 0 0 1 0 0 0 0 0 0 0 0 0 0 0 0 0 0 0 0 0 0 0 0 0 0 1 0 2 1 0 0 0 1 1 0 0 0 0 0 0 0 2 1 1 0 0 0 0 0 2 0 0 0 1 1 0 1 0 0 0 0 0 0 0 0 0 0 1 0 0 1 0 0 0 0 0 0 3 0 0 0 2 0 0 0 1 0 0 0 2 0 1 0 1 0 0 1 1 1 0 2 0 0 0 0 1 0 0 0 0 2 0 0 0 0 1 1 0 0 0 2</intensities>
			</dataPoints>
		</scan>
		<scan appendNumber="0" mode="Continuous" scanAxis="Omega-2Theta" status="Completed">
			<header>
				<startTimeStamp>2016-02-08T09:59:58-08:00</startTimeStamp>
				<endTimeStamp>2016-02-08T10:01:19-08:00</endTimeStamp>
				<author>
					<name>user</name>
				</author>
				<source>
					<applicationSoftware version="4.2a">Data Collector</applicationSoftware>
					<instrumentControlSoftware version="2.2  20130918">XPERT-PRO</instrumentControlSoftware>
					<instrumentID>0000000013085222</instrumentID>
				</source>
			</header>
			<scanAxisCenter>
				<position axis="2Theta" unit="deg">86.8400</position>
				<position axis="Omega" unit="deg">7.0464</position>
			</scanAxisCenter>
			<reflection>
				<material>Si [001]</material>
				<hkl>
					<h>2</h>
					<k>2</k>
					<l>4</l>
				</hkl>
				<unitCell>
					<alpha unit="deg">90.00000</alpha>
					<beta unit="deg">90.00000</beta>
					<gamma unit="deg">90.00000</gamma>
					<a unit="Angstrom">5.43119</a>
					<b unit="Angstrom">5.43119</b>
					<c unit="Angstrom">5.43119</c>
				</unitCell>
			</reflection>
			<dataPoints>
				<positions axis="2Theta" unit="deg">
					<startPosition>84.9800</startPosition>
					<endPosition>88.7000</endPosition>
				</positions>
				<positions axis="Omega" unit="deg">
					<startPosition>6.1164</startPosition>
					<endPosition>7.9764</endPosition>
				</positions>
				<positions axis="Phi" unit="deg">
					<commonPosition>0.00</commonPosition>
				</positions>
				<positions axis="Chi" unit="deg">
					<commonPosition>0.00</commonPosition>
				</positions>
				<positions axis="X" unit="mm">
					<commonPosition>0.00</commonPosition>
				</positions>
				<positions axis="Y" unit="mm">
					<commonPosition>0.00</commonPosition>
				</positions>
				<positions axis="Z" unit="mm">
					<commonPosition>8.416</commonPosition>
				</positions>
				<beamAttenuationFactors>1.00 1.00 1.00 1.00 1.00 1.00 1.00 1.00 1.00 1.00 1.00 1.00 1.00 1.00 1.00 1.00 1.00 1.00 1.00 1.00 1.00 1.00 1.00 1.00 1.00 1.00 1.00 1.00 1.00 1.00 1.00 1.00 1.00 1.00 1.00 1.00 1.00 1.00 1.00 1.00 1.00 1.00 1.00 1.00 1.00 1.00 1.00 1.00 1.00 1.00 1.00 1.00 1.00 1.00 1.00 1.00 1.00 1.00 1.00 1.00 1.00 1.00 1.00 1.00 1.00 1.00 1.00 1.00 1.00 1.00 1.00 1.00 1.00 1.00 1.00 1.00 1.00 1.00 1.00 1.00 1.00 1.00 1.00 1.00 1.00 1.00 1.00 1.00 1.00 1.00 1.00 1.00 1.00 1.00 1.00 1.00 1.00 1.00 1.00 1.00 1.00 1.00 1.00 1.00 1.00 1.00 1.00 1.00 1.00 1.00 1.00 1.00 1.00 1.00 1.00 1.00 1.00 1.00 1.00 1.00 1.00 1.00 1.00 1.00 1.00</beamAttenuationFactors>
				<commonCountingTime unit="seconds">0.50</commonCountingTime>
				<intensities unit="counts">1 0 0 1 1 0 0 0 0 0 0 1 0 0 0 1 0 0 0 0 3 2 2 0 0 1 0 1 0 1 0 0 1 0 0 0 0 1 0 0 0 0 0 1 1 1 1 0 0 0 0 1 0 1 0 1 1 0 0 0 0 0 0 1 0 0 1 0 1 0 1 0 0 0 0 1 2 1 0 0 0 0 2 1 0 0 0 1 1 0 0 0 0 0 0 0 0 0 0 2 1 1 0 0 1 1 0 1 0 0 0 0 0 0 0 0 0 0 2 0 0 0 1 0 0</intensities>
			</dataPoints>
		</scan>
		<scan appendNumber="0" mode="Continuous" scanAxis="Omega-2Theta" status="Completed">
			<header>
				<startTimeStamp>2016-02-08T10:01:36-08:00</startTimeStamp>
				<endTimeStamp>2016-02-08T10:02:56-08:00</endTimeStamp>
				<author>
					<name>user</name>
				</author>
				<source>
					<applicationSoftware version="4.2a">Data Collector</applicationSoftware>
					<instrumentControlSoftware version="2.2  20130918">XPERT-PRO</instrumentControlSoftware>
					<instrumentID>0000000013085222</instrumentID>
				</source>
			</header>
			<scanAxisCenter>
				<position axis="2Theta" unit="deg">86.8400</position>
				<position axis="Omega" unit="deg">7.0614</position>
			</scanAxisCenter>
			<reflection>
				<material>Si [001]</material>
				<hkl>
					<h>2</h>
					<k>2</k>
					<l>4</l>
				</hkl>
				<unitCell>
					<alpha unit="deg">90.00000</alpha>
					<beta unit="deg">90.00000</beta>
					<gamma unit="deg">90.00000</gamma>
					<a unit="Angstrom">5.43119</a>
					<b unit="Angstrom">5.43119</b>
					<c unit="Angstrom">5.43119</c>
				</unitCell>
			</reflection>
			<dataPoints>
				<positions axis="2Theta" unit="deg">
					<startPosition>84.9800</startPosition>
					<endPosition>88.7000</endPosition>
				</positions>
				<positions axis="Omega" unit="deg">
					<startPosition>6.1314</startPosition>
					<endPosition>7.9914</endPosition>
				</positions>
				<positions axis="Phi" unit="deg">
					<commonPosition>0.00</commonPosition>
				</positions>
				<positions axis="Chi" unit="deg">
					<commonPosition>0.00</commonPosition>
				</positions>
				<positions axis="X" unit="mm">
					<commonPosition>0.00</commonPosition>
				</positions>
				<positions axis="Y" unit="mm">
					<commonPosition>0.00</commonPosition>
				</positions>
				<positions axis="Z" unit="mm">
					<commonPosition>8.416</commonPosition>
				</positions>
				<beamAttenuationFactors>1.00 1.00 1.00 1.00 1.00 1.00 1.00 1.00 1.00 1.00 1.00 1.00 1.00 1.00 1.00 1.00 1.00 1.00 1.00 1.00 1.00 1.00 1.00 1.00 1.00 1.00 1.00 1.00 1.00 1.00 1.00 1.00 1.00 1.00 1.00 1.00 1.00 1.00 1.00 1.00 1.00 1.00 1.00 1.00 1.00 1.00 1.00 1.00 1.00 1.00 1.00 1.00 1.00 1.00 1.00 1.00 1.00 1.00 1.00 1.00 1.00 1.00 1.00 1.00 1.00 1.00 1.00 1.00 1.00 1.00 1.00 1.00 1.00 1.00 1.00 1.00 1.00 1.00 1.00 1.00 1.00 1.00 1.00 1.00 1.00 1.00 1.00 1.00 1.00 1.00 1.00 1.00 1.00 1.00 1.00 1.00 1.00 1.00 1.00 1.00 1.00 1.00 1.00 1.00 1.00 1.00 1.00 1.00 1.00 1.00 1.00 1.00 1.00 1.00 1.00 1.00 1.00 1.00 1.00 1.00 1.00 1.00 1.00 1.00 1.00</beamAttenuationFactors>
				<commonCountingTime unit="seconds">0.50</commonCountingTime>
				<intensities unit="counts">0 1 0 1 0 0 0 1 1 0 2 1 0 0 2 1 1 0 0 1 0 2 0 0 0 1 0 0 1 0 0 1 0 0 0 1 1 0 1 0 1 1 0 0 0 0 0 1 0 0 1 0 1 0 1 0 0 0 1 0 0 0 0 1 1 0 1 0 0 1 3 1 2 1 0 2 0 1 1 1 1 0 0 0 1 3 1 0 2 1 0 1 0 0 2 1 0 0 0 0 0 0 2 1 1 1 0 1 0 2 1 0 1 0 1 1 1 0 0 0 0 2 1 0 1</intensities>
			</dataPoints>
		</scan>
		<scan appendNumber="0" mode="Continuous" scanAxis="Omega-2Theta" status="Completed">
			<header>
				<startTimeStamp>2016-02-08T10:03:12-08:00</startTimeStamp>
				<endTimeStamp>2016-02-08T10:04:37-08:00</endTimeStamp>
				<author>
					<name>user</name>
				</author>
				<source>
					<applicationSoftware version="4.2a">Data Collector</applicationSoftware>
					<instrumentControlSoftware version="2.2  20130918">XPERT-PRO</instrumentControlSoftware>
					<instrumentID>0000000013085222</instrumentID>
				</source>
			</header>
			<scanAxisCenter>
				<position axis="2Theta" unit="deg">86.8400</position>
				<position axis="Omega" unit="deg">7.0764</position>
			</scanAxisCenter>
			<reflection>
				<material>Si [001]</material>
				<hkl>
					<h>2</h>
					<k>2</k>
					<l>4</l>
				</hkl>
				<unitCell>
					<alpha unit="deg">90.00000</alpha>
					<beta unit="deg">90.00000</beta>
					<gamma unit="deg">90.00000</gamma>
					<a unit="Angstrom">5.43119</a>
					<b unit="Angstrom">5.43119</b>
					<c unit="Angstrom">5.43119</c>
				</unitCell>
			</reflection>
			<dataPoints>
				<positions axis="2Theta" unit="deg">
					<startPosition>84.9800</startPosition>
					<endPosition>88.7000</endPosition>
				</positions>
				<positions axis="Omega" unit="deg">
					<startPosition>6.1464</startPosition>
					<endPosition>8.0064</endPosition>
				</positions>
				<positions axis="Phi" unit="deg">
					<commonPosition>0.00</commonPosition>
				</positions>
				<positions axis="Chi" unit="deg">
					<commonPosition>0.00</commonPosition>
				</positions>
				<positions axis="X" unit="mm">
					<commonPosition>0.00</commonPosition>
				</positions>
				<positions axis="Y" unit="mm">
					<commonPosition>0.00</commonPosition>
				</positions>
				<positions axis="Z" unit="mm">
					<commonPosition>8.416</commonPosition>
				</positions>
				<beamAttenuationFactors>1.00 1.00 1.00 1.00 1.00 1.00 1.00 1.00 1.00 1.00 1.00 1.00 1.00 1.00 1.00 1.00 1.00 1.00 1.00 1.00 1.00 1.00 1.00 1.00 1.00 1.00 1.00 1.00 1.00 1.00 1.00 1.00 1.00 1.00 1.00 1.00 1.00 1.00 1.00 1.00 1.00 1.00 1.00 1.00 1.00 1.00 1.00 1.00 1.00 1.00 1.00 1.00 1.00 1.00 1.00 1.00 1.00 1.00 1.00 1.00 1.00 1.00 1.00 1.00 1.00 1.00 1.00 1.00 1.00 1.00 1.00 1.00 1.00 1.00 1.00 1.00 1.00 1.00 1.00 1.00 1.00 1.00 1.00 1.00 1.00 1.00 1.00 1.00 1.00 1.00 1.00 1.00 1.00 1.00 1.00 1.00 1.00 1.00 1.00 1.00 1.00 1.00 1.00 1.00 1.00 1.00 1.00 1.00 1.00 1.00 1.00 1.00 1.00 1.00 1.00 1.00 1.00 1.00 1.00 1.00 1.00 1.00 1.00 1.00 1.00</beamAttenuationFactors>
				<commonCountingTime unit="seconds">0.50</commonCountingTime>
				<intensities unit="counts">0 0 1 0 2 0 0 0 0 1 0 0 0 0 1 0 1 1 0 1 0 1 0 0 0 0 1 0 0 0 2 0 1 1 0 2 2 0 1 0 0 0 2 1 0 0 0 0 0 0 0 2 0 0 0 0 1 1 1 1 0 0 2 0 0 1 2 0 0 1 0 1 1 0 2 1 0 0 1 0 1 0 1 0 0 0 0 1 0 0 0 1 0 2 0 0 0 1 1 4 1 0 0 0 1 1 0 0 1 0 0 1 0 2 0 1 0 1 0 0 0 0 1 0 0</intensities>
			</dataPoints>
		</scan>
		<scan appendNumber="0" mode="Continuous" scanAxis="Omega-2Theta" status="Completed">
			<header>
				<startTimeStamp>2016-02-08T10:04:54-08:00</startTimeStamp>
				<endTimeStamp>2016-02-08T10:06:16-08:00</endTimeStamp>
				<author>
					<name>user</name>
				</author>
				<source>
					<applicationSoftware version="4.2a">Data Collector</applicationSoftware>
					<instrumentControlSoftware version="2.2  20130918">XPERT-PRO</instrumentControlSoftware>
					<instrumentID>0000000013085222</instrumentID>
				</source>
			</header>
			<scanAxisCenter>
				<position axis="2Theta" unit="deg">86.8400</position>
				<position axis="Omega" unit="deg">7.0914</position>
			</scanAxisCenter>
			<reflection>
				<material>Si [001]</material>
				<hkl>
					<h>2</h>
					<k>2</k>
					<l>4</l>
				</hkl>
				<unitCell>
					<alpha unit="deg">90.00000</alpha>
					<beta unit="deg">90.00000</beta>
					<gamma unit="deg">90.00000</gamma>
					<a unit="Angstrom">5.43119</a>
					<b unit="Angstrom">5.43119</b>
					<c unit="Angstrom">5.43119</c>
				</unitCell>
			</reflection>
			<dataPoints>
				<positions axis="2Theta" unit="deg">
					<startPosition>84.9800</startPosition>
					<endPosition>88.7000</endPosition>
				</positions>
				<positions axis="Omega" unit="deg">
					<startPosition>6.1614</startPosition>
					<endPosition>8.0214</endPosition>
				</positions>
				<positions axis="Phi" unit="deg">
					<commonPosition>0.00</commonPosition>
				</positions>
				<positions axis="Chi" unit="deg">
					<commonPosition>0.00</commonPosition>
				</positions>
				<positions axis="X" unit="mm">
					<commonPosition>0.00</commonPosition>
				</positions>
				<positions axis="Y" unit="mm">
					<commonPosition>0.00</commonPosition>
				</positions>
				<positions axis="Z" unit="mm">
					<commonPosition>8.416</commonPosition>
				</positions>
				<beamAttenuationFactors>1.00 1.00 1.00 1.00 1.00 1.00 1.00 1.00 1.00 1.00 1.00 1.00 1.00 1.00 1.00 1.00 1.00 1.00 1.00 1.00 1.00 1.00 1.00 1.00 1.00 1.00 1.00 1.00 1.00 1.00 1.00 1.00 1.00 1.00 1.00 1.00 1.00 1.00 1.00 1.00 1.00 1.00 1.00 1.00 1.00 1.00 1.00 1.00 1.00 1.00 1.00 1.00 1.00 1.00 1.00 1.00 1.00 1.00 1.00 1.00 1.00 1.00 1.00 1.00 1.00 1.00 1.00 1.00 1.00 1.00 1.00 1.00 1.00 1.00 1.00 1.00 1.00 1.00 1.00 1.00 1.00 1.00 1.00 1.00 1.00 1.00 1.00 1.00 1.00 1.00 1.00 1.00 1.00 1.00 1.00 1.00 1.00 1.00 1.00 1.00 1.00 1.00 1.00 1.00 1.00 1.00 1.00 1.00 1.00 1.00 1.00 1.00 1.00 1.00 1.00 1.00 1.00 1.00 1.00 1.00 1.00 1.00 1.00 1.00 1.00</beamAttenuationFactors>
				<commonCountingTime unit="seconds">0.50</commonCountingTime>
				<intensities unit="counts">0 0 0 0 0 1 0 0 0 2 0 0 1 0 1 1 2 0 1 0 0 0 1 0 1 0 1 0 1 0 1 0 0 0 0 0 0 0 0 3 1 1 1 0 0 0 0 0 0 0 0 0 0 1 0 0 0 0 0 0 1 0 1 1 2 0 0 1 0 1 0 1 0 2 0 1 0 0 2 0 1 0 0 1 1 1 1 2 0 0 1 1 1 0 0 1 0 0 0 0 0 0 0 1 2 0 0 2 0 0 1 0 0 1 3 1 1 0 1 1 0 0 4 1 0</intensities>
			</dataPoints>
		</scan>
		<scan appendNumber="0" mode="Continuous" scanAxis="Omega-2Theta" status="Completed">
			<header>
				<startTimeStamp>2016-02-08T10:06:31-08:00</startTimeStamp>
				<endTimeStamp>2016-02-08T10:07:55-08:00</endTimeStamp>
				<author>
					<name>user</name>
				</author>
				<source>
					<applicationSoftware version="4.2a">Data Collector</applicationSoftware>
					<instrumentControlSoftware version="2.2  20130918">XPERT-PRO</instrumentControlSoftware>
					<instrumentID>0000000013085222</instrumentID>
				</source>
			</header>
			<scanAxisCenter>
				<position axis="2Theta" unit="deg">86.8400</position>
				<position axis="Omega" unit="deg">7.1064</position>
			</scanAxisCenter>
			<reflection>
				<material>Si [001]</material>
				<hkl>
					<h>2</h>
					<k>2</k>
					<l>4</l>
				</hkl>
				<unitCell>
					<alpha unit="deg">90.00000</alpha>
					<beta unit="deg">90.00000</beta>
					<gamma unit="deg">90.00000</gamma>
					<a unit="Angstrom">5.43119</a>
					<b unit="Angstrom">5.43119</b>
					<c unit="Angstrom">5.43119</c>
				</unitCell>
			</reflection>
			<dataPoints>
				<positions axis="2Theta" unit="deg">
					<startPosition>84.9800</startPosition>
					<endPosition>88.7000</endPosition>
				</positions>
				<positions axis="Omega" unit="deg">
					<startPosition>6.1764</startPosition>
					<endPosition>8.0364</endPosition>
				</positions>
				<positions axis="Phi" unit="deg">
					<commonPosition>0.00</commonPosition>
				</positions>
				<positions axis="Chi" unit="deg">
					<commonPosition>0.00</commonPosition>
				</positions>
				<positions axis="X" unit="mm">
					<commonPosition>0.00</commonPosition>
				</positions>
				<positions axis="Y" unit="mm">
					<commonPosition>0.00</commonPosition>
				</positions>
				<positions axis="Z" unit="mm">
					<commonPosition>8.416</commonPosition>
				</positions>
				<beamAttenuationFactors>1.00 1.00 1.00 1.00 1.00 1.00 1.00 1.00 1.00 1.00 1.00 1.00 1.00 1.00 1.00 1.00 1.00 1.00 1.00 1.00 1.00 1.00 1.00 1.00 1.00 1.00 1.00 1.00 1.00 1.00 1.00 1.00 1.00 1.00 1.00 1.00 1.00 1.00 1.00 1.00 1.00 1.00 1.00 1.00 1.00 1.00 1.00 1.00 1.00 1.00 1.00 1.00 1.00 1.00 1.00 1.00 1.00 1.00 1.00 1.00 1.00 1.00 1.00 1.00 1.00 1.00 1.00 1.00 1.00 1.00 1.00 1.00 1.00 1.00 1.00 1.00 1.00 1.00 1.00 1.00 1.00 1.00 1.00 1.00 1.00 1.00 1.00 1.00 1.00 1.00 1.00 1.00 1.00 1.00 1.00 1.00 1.00 1.00 1.00 1.00 1.00 1.00 1.00 1.00 1.00 1.00 1.00 1.00 1.00 1.00 1.00 1.00 1.00 1.00 1.00 1.00 1.00 1.00 1.00 1.00 1.00 1.00 1.00 1.00 1.00</beamAttenuationFactors>
				<commonCountingTime unit="seconds">0.50</commonCountingTime>
				<intensities unit="counts">0 0 1 1 0 1 0 0 0 0 0 0 0 0 0 0 0 0 0 0 0 1 0 1 0 0 0 1 1 0 1 0 2 0 0 0 0 0 1 0 0 0 0 2 0 0 1 0 3 0 0 1 0 0 0 1 1 0 1 0 1 1 2 2 1 0 0 0 0 0 0 1 0 0 0 1 0 0 1 0 0 0 0 1 0 0 1 1 0 1 1 2 0 0 0 0 0 0 0 1 0 0 3 2 1 0 0 0 2 1 0 0 2 1 0 0 0 0 0 0 0 1 0 0 0</intensities>
			</dataPoints>
		</scan>
		<scan appendNumber="0" mode="Continuous" scanAxis="Omega-2Theta" status="Completed">
			<header>
				<startTimeStamp>2016-02-08T10:08:11-08:00</startTimeStamp>
				<endTimeStamp>2016-02-08T10:09:30-08:00</endTimeStamp>
				<author>
					<name>user</name>
				</author>
				<source>
					<applicationSoftware version="4.2a">Data Collector</applicationSoftware>
					<instrumentControlSoftware version="2.2  20130918">XPERT-PRO</instrumentControlSoftware>
					<instrumentID>0000000013085222</instrumentID>
				</source>
			</header>
			<scanAxisCenter>
				<position axis="2Theta" unit="deg">86.8400</position>
				<position axis="Omega" unit="deg">7.1214</position>
			</scanAxisCenter>
			<reflection>
				<material>Si [001]</material>
				<hkl>
					<h>2</h>
					<k>2</k>
					<l>4</l>
				</hkl>
				<unitCell>
					<alpha unit="deg">90.00000</alpha>
					<beta unit="deg">90.00000</beta>
					<gamma unit="deg">90.00000</gamma>
					<a unit="Angstrom">5.43119</a>
					<b unit="Angstrom">5.43119</b>
					<c unit="Angstrom">5.43119</c>
				</unitCell>
			</reflection>
			<dataPoints>
				<positions axis="2Theta" unit="deg">
					<startPosition>84.9800</startPosition>
					<endPosition>88.7000</endPosition>
				</positions>
				<positions axis="Omega" unit="deg">
					<startPosition>6.1914</startPosition>
					<endPosition>8.0514</endPosition>
				</positions>
				<positions axis="Phi" unit="deg">
					<commonPosition>0.00</commonPosition>
				</positions>
				<positions axis="Chi" unit="deg">
					<commonPosition>0.00</commonPosition>
				</positions>
				<positions axis="X" unit="mm">
					<commonPosition>0.00</commonPosition>
				</positions>
				<positions axis="Y" unit="mm">
					<commonPosition>0.00</commonPosition>
				</positions>
				<positions axis="Z" unit="mm">
					<commonPosition>8.416</commonPosition>
				</positions>
				<beamAttenuationFactors>1.00 1.00 1.00 1.00 1.00 1.00 1.00 1.00 1.00 1.00 1.00 1.00 1.00 1.00 1.00 1.00 1.00 1.00 1.00 1.00 1.00 1.00 1.00 1.00 1.00 1.00 1.00 1.00 1.00 1.00 1.00 1.00 1.00 1.00 1.00 1.00 1.00 1.00 1.00 1.00 1.00 1.00 1.00 1.00 1.00 1.00 1.00 1.00 1.00 1.00 1.00 1.00 1.00 1.00 1.00 1.00 1.00 1.00 1.00 1.00 1.00 1.00 1.00 1.00 1.00 1.00 1.00 1.00 1.00 1.00 1.00 1.00 1.00 1.00 1.00 1.00 1.00 1.00 1.00 1.00 1.00 1.00 1.00 1.00 1.00 1.00 1.00 1.00 1.00 1.00 1.00 1.00 1.00 1.00 1.00 1.00 1.00 1.00 1.00 1.00 1.00 1.00 1.00 1.00 1.00 1.00 1.00 1.00 1.00 1.00 1.00 1.00 1.00 1.00 1.00 1.00 1.00 1.00 1.00 1.00 1.00 1.00 1.00 1.00 1.00</beamAttenuationFactors>
				<commonCountingTime unit="seconds">0.50</commonCountingTime>
				<intensities unit="counts">0 0 0 0 0 0 0 0 0 0 0 0 0 0 0 1 0 0 0 1 0 0 0 0 0 0 0 0 0 1 0 1 1 0 1 0 0 2 0 0 1 0 0 0 0 0 0 0 0 0 2 1 0 0 0 0 0 0 0 0 0 0 0 0 0 0 0 1 0 0 1 0 0 0 0 2 0 1 1 0 0 0 0 0 1 1 0 0 0 0 2 1 1 0 0 0 1 1 0 0 2 0 0 1 1 1 1 0 0 1 0 0 0 0 1 0 0 1 0 1 0 0 0 0 0</intensities>
			</dataPoints>
		</scan>
		<scan appendNumber="0" mode="Continuous" scanAxis="Omega-2Theta" status="Completed">
			<header>
				<startTimeStamp>2016-02-08T10:09:48-08:00</startTimeStamp>
				<endTimeStamp>2016-02-08T10:11:10-08:00</endTimeStamp>
				<author>
					<name>user</name>
				</author>
				<source>
					<applicationSoftware version="4.2a">Data Collector</applicationSoftware>
					<instrumentControlSoftware version="2.2  20130918">XPERT-PRO</instrumentControlSoftware>
					<instrumentID>0000000013085222</instrumentID>
				</source>
			</header>
			<scanAxisCenter>
				<position axis="2Theta" unit="deg">86.8400</position>
				<position axis="Omega" unit="deg">7.1364</position>
			</scanAxisCenter>
			<reflection>
				<material>Si [001]</material>
				<hkl>
					<h>2</h>
					<k>2</k>
					<l>4</l>
				</hkl>
				<unitCell>
					<alpha unit="deg">90.00000</alpha>
					<beta unit="deg">90.00000</beta>
					<gamma unit="deg">90.00000</gamma>
					<a unit="Angstrom">5.43119</a>
					<b unit="Angstrom">5.43119</b>
					<c unit="Angstrom">5.43119</c>
				</unitCell>
			</reflection>
			<dataPoints>
				<positions axis="2Theta" unit="deg">
					<startPosition>84.9800</startPosition>
					<endPosition>88.7000</endPosition>
				</positions>
				<positions axis="Omega" unit="deg">
					<startPosition>6.2064</startPosition>
					<endPosition>8.0664</endPosition>
				</positions>
				<positions axis="Phi" unit="deg">
					<commonPosition>0.00</commonPosition>
				</positions>
				<positions axis="Chi" unit="deg">
					<commonPosition>0.00</commonPosition>
				</positions>
				<positions axis="X" unit="mm">
					<commonPosition>0.00</commonPosition>
				</positions>
				<positions axis="Y" unit="mm">
					<commonPosition>0.00</commonPosition>
				</positions>
				<positions axis="Z" unit="mm">
					<commonPosition>8.416</commonPosition>
				</positions>
				<beamAttenuationFactors>1.00 1.00 1.00 1.00 1.00 1.00 1.00 1.00 1.00 1.00 1.00 1.00 1.00 1.00 1.00 1.00 1.00 1.00 1.00 1.00 1.00 1.00 1.00 1.00 1.00 1.00 1.00 1.00 1.00 1.00 1.00 1.00 1.00 1.00 1.00 1.00 1.00 1.00 1.00 1.00 1.00 1.00 1.00 1.00 1.00 1.00 1.00 1.00 1.00 1.00 1.00 1.00 1.00 1.00 1.00 1.00 1.00 1.00 1.00 1.00 1.00 1.00 1.00 1.00 1.00 1.00 1.00 1.00 1.00 1.00 1.00 1.00 1.00 1.00 1.00 1.00 1.00 1.00 1.00 1.00 1.00 1.00 1.00 1.00 1.00 1.00 1.00 1.00 1.00 1.00 1.00 1.00 1.00 1.00 1.00 1.00 1.00 1.00 1.00 1.00 1.00 1.00 1.00 1.00 1.00 1.00 1.00 1.00 1.00 1.00 1.00 1.00 1.00 1.00 1.00 1.00 1.00 1.00 1.00 1.00 1.00 1.00 1.00 1.00 1.00</beamAttenuationFactors>
				<commonCountingTime unit="seconds">0.50</commonCountingTime>
				<intensities unit="counts">0 0 0 0 0 0 0 0 1 0 0 1 0 1 1 1 2 1 2 1 1 0 2 0 0 0 0 1 1 0 2 0 0 1 0 0 0 0 0 2 0 0 0 2 0 0 0 0 1 0 0 1 0 0 0 0 0 1 0 1 0 1 1 0 0 0 0 0 4 0 0 0 0 0 2 0 0 1 0 0 0 1 1 0 0 0 1 0 1 0 0 1 0 1 0 0 0 1 0 0 0 0 0 1 0 0 0 0 2 2 0 0 0 2 0 0 0 1 2 0 0 0 1 0 1</intensities>
			</dataPoints>
		</scan>
		<scan appendNumber="0" mode="Continuous" scanAxis="Omega-2Theta" status="Completed">
			<header>
				<startTimeStamp>2016-02-08T10:11:25-08:00</startTimeStamp>
				<endTimeStamp>2016-02-08T10:12:48-08:00</endTimeStamp>
				<author>
					<name>user</name>
				</author>
				<source>
					<applicationSoftware version="4.2a">Data Collector</applicationSoftware>
					<instrumentControlSoftware version="2.2  20130918">XPERT-PRO</instrumentControlSoftware>
					<instrumentID>0000000013085222</instrumentID>
				</source>
			</header>
			<scanAxisCenter>
				<position axis="2Theta" unit="deg">86.8400</position>
				<position axis="Omega" unit="deg">7.1514</position>
			</scanAxisCenter>
			<reflection>
				<material>Si [001]</material>
				<hkl>
					<h>2</h>
					<k>2</k>
					<l>4</l>
				</hkl>
				<unitCell>
					<alpha unit="deg">90.00000</alpha>
					<beta unit="deg">90.00000</beta>
					<gamma unit="deg">90.00000</gamma>
					<a unit="Angstrom">5.43119</a>
					<b unit="Angstrom">5.43119</b>
					<c unit="Angstrom">5.43119</c>
				</unitCell>
			</reflection>
			<dataPoints>
				<positions axis="2Theta" unit="deg">
					<startPosition>84.9800</startPosition>
					<endPosition>88.7000</endPosition>
				</positions>
				<positions axis="Omega" unit="deg">
					<startPosition>6.2214</startPosition>
					<endPosition>8.0814</endPosition>
				</positions>
				<positions axis="Phi" unit="deg">
					<commonPosition>0.00</commonPosition>
				</positions>
				<positions axis="Chi" unit="deg">
					<commonPosition>0.00</commonPosition>
				</positions>
				<positions axis="X" unit="mm">
					<commonPosition>0.00</commonPosition>
				</positions>
				<positions axis="Y" unit="mm">
					<commonPosition>0.00</commonPosition>
				</positions>
				<positions axis="Z" unit="mm">
					<commonPosition>8.416</commonPosition>
				</positions>
				<beamAttenuationFactors>1.00 1.00 1.00 1.00 1.00 1.00 1.00 1.00 1.00 1.00 1.00 1.00 1.00 1.00 1.00 1.00 1.00 1.00 1.00 1.00 1.00 1.00 1.00 1.00 1.00 1.00 1.00 1.00 1.00 1.00 1.00 1.00 1.00 1.00 1.00 1.00 1.00 1.00 1.00 1.00 1.00 1.00 1.00 1.00 1.00 1.00 1.00 1.00 1.00 1.00 1.00 1.00 1.00 1.00 1.00 1.00 1.00 1.00 1.00 1.00 1.00 1.00 1.00 1.00 1.00 1.00 1.00 1.00 1.00 1.00 1.00 1.00 1.00 1.00 1.00 1.00 1.00 1.00 1.00 1.00 1.00 1.00 1.00 1.00 1.00 1.00 1.00 1.00 1.00 1.00 1.00 1.00 1.00 1.00 1.00 1.00 1.00 1.00 1.00 1.00 1.00 1.00 1.00 1.00 1.00 1.00 1.00 1.00 1.00 1.00 1.00 1.00 1.00 1.00 1.00 1.00 1.00 1.00 1.00 1.00 1.00 1.00 1.00 1.00 1.00</beamAttenuationFactors>
				<commonCountingTime unit="seconds">0.50</commonCountingTime>
				<intensities unit="counts">0 0 0 0 0 0 0 0 0 0 0 0 1 0 0 0 0 1 1 0 0 0 0 0 2 2 1 0 1 0 0 2 0 0 0 0 1 0 0 1 0 0 0 0 0 0 1 0 0 0 1 0 0 0 0 1 1 1 0 0 1 0 0 0 0 1 0 0 0 1 1 0 1 0 0 0 0 1 1 0 0 1 0 0 0 0 0 2 0 0 0 0 0 0 1 0 0 0 0 1 0 0 1 0 1 0 0 2 1 0 0 2 0 3 0 0 0 0 0 1 0 2 1 1 0</intensities>
			</dataPoints>
		</scan>
		<scan appendNumber="0" mode="Continuous" scanAxis="Omega-2Theta" status="Completed">
			<header>
				<startTimeStamp>2016-02-08T10:13:07-08:00</startTimeStamp>
				<endTimeStamp>2016-02-08T10:14:28-08:00</endTimeStamp>
				<author>
					<name>user</name>
				</author>
				<source>
					<applicationSoftware version="4.2a">Data Collector</applicationSoftware>
					<instrumentControlSoftware version="2.2  20130918">XPERT-PRO</instrumentControlSoftware>
					<instrumentID>0000000013085222</instrumentID>
				</source>
			</header>
			<scanAxisCenter>
				<position axis="2Theta" unit="deg">86.8400</position>
				<position axis="Omega" unit="deg">7.1664</position>
			</scanAxisCenter>
			<reflection>
				<material>Si [001]</material>
				<hkl>
					<h>2</h>
					<k>2</k>
					<l>4</l>
				</hkl>
				<unitCell>
					<alpha unit="deg">90.00000</alpha>
					<beta unit="deg">90.00000</beta>
					<gamma unit="deg">90.00000</gamma>
[...]
				<hkl>
					<h>2</h>
					<k>2</k>
					<l>4</l>
				</hkl>
				<unitCell>
					<alpha unit="deg">90.00000</alpha>
					<beta unit="deg">90.00000</beta>
					<gamma unit="deg">90.00000</gamma>
					<a unit="Angstrom">5.43119</a>
					<b unit="Angstrom">5.43119</b>
					<c unit="Angstrom">5.43119</c>
				</unitCell>
			</reflection>
			<dataPoints>
				<positions axis="2Theta" unit="deg">
					<startPosition>84.9800</startPosition>
					<endPosition>88.7000</endPosition>
				</positions>
				<positions axis="Omega" unit="deg">
					<startPosition>7.2564</startPosition>
					<endPosition>9.1164</endPosition>
				</positions>
				<positions axis="Phi" unit="deg">
					<commonPosition>0.00</commonPosition>
				</positions>
				<positions axis="Chi" unit="deg">
					<commonPosition>0.00</commonPosition>
				</positions>
				<positions axis="X" unit="mm">
					<commonPosition>0.00</commonPosition>
				</positions>
				<positions axis="Y" unit="mm">
					<commonPosition>0.00</commonPosition>
				</positions>
				<positions axis="Z" unit="mm">
					<commonPosition>8.416</commonPosition>
				</positions>
				<beamAttenuationFactors>1.00 1.00 1.00 1.00 1.00 1.00 1.00 1.00 1.00 1.00 1.00 1.00 1.00 1.00 1.00 1.00 1.00 1.00 1.00 1.00 1.00 1.00 1.00 1.00 1.00 1.00 1.00 1.00 1.00 1.00 1.00 1.00 1.00 1.00 1.00 1.00 1.00 1.00 1.00 1.00 1.00 1.00 1.00 1.00 1.00 1.00 1.00 1.00 1.00 1.00 1.00 1.00 1.00 1.00 1.00 1.00 1.00 1.00 1.00 1.00 1.00 1.00 1.00 1.00 1.00 1.00 1.00 1.00 1.00 1.00 1.00 1.00 1.00 1.00 1.00 1.00 1.00 1.00 1.00 1.00 1.00 1.00 1.00 1.00 1.00 1.00 1.00 1.00 1.00 1.00 1.00 1.00 1.00 1.00 1.00 1.00 1.00 1.00 1.00 1.00 1.00 1.00 1.00 1.00 1.00 1.00 1.00 1.00 1.00 1.00 1.00 1.00 1.00 1.00 1.00 1.00 1.00 1.00 1.00 1.00 1.00 1.00 1.00 1.00 1.00</beamAttenuationFactors>
				<commonCountingTime unit="seconds">0.50</commonCountingTime>
				<intensities unit="counts">0 0 0 2 1 2 0 0 0 1 0 1 1 1 2 3 2 2 2 1 2 4 7 8 12 16 35 52 96 114 102 97 61 60 48 22 24 15 22 16 13 9 11 11 5 5 4 3 5 2 1 3 1 0 1 1 1 0 1 2 1 0 4 0 1 0 1 2 2 1 0 0 0 1 1 0 0 0 1 4 2 1 2 1 0 2 0 4 4 1 3 2 6 7 6 11 15 31 57 132 288 555 729 507 290 116 66 19 18 10 3 4 5 4 2 1 1 1 1 3 1 1 1 2 0</intensities>
			</dataPoints>
		</scan>
		<scan appendNumber="0" mode="Continuous" scanAxis="Omega-2Theta" status="Completed">
			<header>
				<startTimeStamp>2016-02-08T12:07:16-08:00</startTimeStamp>
				<endTimeStamp>2016-02-08T12:08:45-08:00</endTimeStamp>
				<author>
					<name>user</name>
				</author>
				<source>
					<applicationSoftware version="4.2a">Data Collector</applicationSoftware>
					<instrumentControlSoftware version="2.2  20130918">XPERT-PRO</instrumentControlSoftware>
					<instrumentID>0000000013085222</instrumentID>
				</source>
			</header>
			<scanAxisCenter>
				<position axis="2Theta" unit="deg">86.8400</position>
				<position axis="Omega" unit="deg">8.2014</position>
			</scanAxisCenter>
			<reflection>
				<material>Si [001]</material>
				<hkl>
					<h>2</h>
					<k>2</k>
					<l>4</l>
				</hkl>
				<unitCell>
					<alpha unit="deg">90.00000</alpha>
					<beta unit="deg">90.00000</beta>
					<gamma unit="deg">90.00000</gamma>
					<a unit="Angstrom">5.43119</a>
					<b unit="Angstrom">5.43119</b>
					<c unit="Angstrom">5.43119</c>
				</unitCell>
			</reflection>
			<dataPoints>
				<positions axis="2Theta" unit="deg">
					<startPosition>84.9800</startPosition>
					<endPosition>88.7000</endPosition>
				</positions>
				<positions axis="Omega" unit="deg">
					<startPosition>7.2714</startPosition>
					<endPosition>9.1314</endPosition>
				</positions>
				<positions axis="Phi" unit="deg">
					<commonPosition>0.00</commonPosition>
				</positions>
				<positions axis="Chi" unit="deg">
					<commonPosition>0.00</commonPosition>
				</positions>
				<positions axis="X" unit="mm">
					<commonPosition>0.00</commonPosition>
				</positions>
				<positions axis="Y" unit="mm">
					<commonPosition>0.00</commonPosition>
				</positions>
				<positions axis="Z" unit="mm">
					<commonPosition>8.416</commonPosition>
				</positions>
				<beamAttenuationFactors>1.00 1.00 1.00 1.00 1.00 1.00 1.00 1.00 1.00 1.00 1.00 1.00 1.00 1.00 1.00 1.00 1.00 1.00 1.00 1.00 1.00 1.00 1.00 1.00 1.00 1.00 1.00 1.00 1.00 1.00 1.00 1.00 1.00 1.00 1.00 1.00 1.00 1.00 1.00 1.00 1.00 1.00 1.00 1.00 1.00 1.00 1.00 1.00 1.00 1.00 1.00 1.00 1.00 1.00 1.00 1.00 1.00 1.00 1.00 1.00 1.00 1.00 1.00 1.00 1.00 1.00 1.00 1.00 1.00 1.00 1.00 1.00 1.00 1.00 1.00 1.00 1.00 1.00 1.00 1.00 1.00 1.00 1.00 1.00 1.00 1.00 1.00 1.00 1.00 1.00 1.00 1.00 1.00 1.00 1.00 1.00 1.00 1.00 1.00 1.00 1.00 1.00 1.00 1.00 1.00 1.00 1.00 1.00 1.00 1.00 1.00 1.00 1.00 1.00 1.00 1.00 1.00 1.00 1.00 1.00 1.00 1.00 1.00 1.00 1.00</beamAttenuationFactors>
				<commonCountingTime unit="seconds">0.50</commonCountingTime>
				<intensities unit="counts">0 0 0 1 1 0 1 0 2 1 1 0 1 0 0 0 2 6 0 0 2 5 8 11 11 28 35 67 91 89 95 81 76 46 26 30 25 21 15 10 12 11 11 5 5 7 6 4 4 3 5 4 2 1 0 0 2 0 1 1 0 1 0 0 1 0 0 0 0 0 0 0 0 1 0 0 1 1 2 1 0 1 3 1 1 3 2 3 2 1 3 2 1 8 7 9 22 22 47 84 169 256 320 275 164 93 40 27 23 11 12 2 5 4 5 2 3 0 1 2 2 1 1 0 2</intensities>
			</dataPoints>
		</scan>
		<scan appendNumber="0" mode="Continuous" scanAxis="Omega-2Theta" status="Completed">
			<header>
				<startTimeStamp>2016-02-08T12:09:03-08:00</startTimeStamp>
				<endTimeStamp>2016-02-08T12:10:24-08:00</endTimeStamp>
				<author>
					<name>user</name>
				</author>
				<source>
					<applicationSoftware version="4.2a">Data Collector</applicationSoftware>
					<instrumentControlSoftware version="2.2  20130918">XPERT-PRO</instrumentControlSoftware>
					<instrumentID>0000000013085222</instrumentID>
				</source>
			</header>
			<scanAxisCenter>
				<position axis="2Theta" unit="deg">86.8400</position>
				<position axis="Omega" unit="deg">8.2164</position>
			</scanAxisCenter>
			<reflection>
				<material>Si [001]</material>
				<hkl>
					<h>2</h>
					<k>2</k>
					<l>4</l>
				</hkl>
				<unitCell>
					<alpha unit="deg">90.00000</alpha>
					<beta unit="deg">90.00000</beta>
					<gamma unit="deg">90.00000</gamma>
					<a unit="Angstrom">5.43119</a>
					<b unit="Angstrom">5.43119</b>
					<c unit="Angstrom">5.43119</c>
				</unitCell>
			</reflection>
			<dataPoints>
				<positions axis="2Theta" unit="deg">
					<startPosition>84.9800</startPosition>
					<endPosition>88.7000</endPosition>
				</positions>
				<positions axis="Omega" unit="deg">
					<startPosition>7.2864</startPosition>
					<endPosition>9.1464</endPosition>
				</positions>
				<positions axis="Phi" unit="deg">
					<commonPosition>0.00</commonPosition>
				</positions>
				<positions axis="Chi" unit="deg">
					<commonPosition>0.00</commonPosition>
				</positions>
				<positions axis="X" unit="mm">
					<commonPosition>0.00</commonPosition>
				</positions>
				<positions axis="Y" unit="mm">
					<commonPosition>0.00</commonPosition>
				</positions>
				<positions axis="Z" unit="mm">
					<commonPosition>8.416</commonPosition>
				</positions>
				<beamAttenuationFactors>1.00 1.00 1.00 1.00 1.00 1.00 1.00 1.00 1.00 1.00 1.00 1.00 1.00 1.00 1.00 1.00 1.00 1.00 1.00 1.00 1.00 1.00 1.00 1.00 1.00 1.00 1.00 1.00 1.00 1.00 1.00 1.00 1.00 1.00 1.00 1.00 1.00 1.00 1.00 1.00 1.00 1.00 1.00 1.00 1.00 1.00 1.00 1.00 1.00 1.00 1.00 1.00 1.00 1.00 1.00 1.00 1.00 1.00 1.00 1.00 1.00 1.00 1.00 1.00 1.00 1.00 1.00 1.00 1.00 1.00 1.00 1.00 1.00 1.00 1.00 1.00 1.00 1.00 1.00 1.00 1.00 1.00 1.00 1.00 1.00 1.00 1.00 1.00 1.00 1.00 1.00 1.00 1.00 1.00 1.00 1.00 1.00 1.00 1.00 1.00 1.00 1.00 1.00 1.00 1.00 1.00 1.00 1.00 1.00 1.00 1.00 1.00 1.00 1.00 1.00 1.00 1.00 1.00 1.00 1.00 1.00 1.00 1.00 1.00 1.00</beamAttenuationFactors>
				<commonCountingTime unit="seconds">0.50</commonCountingTime>
				<intensities unit="counts">0 0 1 0 3 1 1 0 1 0 0 3 0 0 1 2 0 1 1 3 4 3 5 11 10 17 23 55 65 87 104 84 62 40 24 25 23 14 19 10 9 11 8 9 8 3 3 2 6 2 4 1 2 0 3 2 4 0 3 1 2 1 0 1 0 1 1 0 2 0 0 1 0 0 0 0 1 0 2 0 1 0 1 3 2 1 2 0 3 4 4 3 4 10 8 12 13 34 36 57 93 140 176 152 119 58 48 25 20 10 9 6 2 5 2 2 5 3 2 2 1 0 0 2 1</intensities>
			</dataPoints>
		</scan>
		<scan appendNumber="0" mode="Continuous" scanAxis="Omega-2Theta" status="Completed">
			<header>
				<startTimeStamp>2016-02-08T12:10:40-08:00</startTimeStamp>
				<endTimeStamp>2016-02-08T12:11:59-08:00</endTimeStamp>
				<author>
					<name>user</name>
				</author>
				<source>
					<applicationSoftware version="4.2a">Data Collector</applicationSoftware>
					<instrumentControlSoftware version="2.2  20130918">XPERT-PRO</instrumentControlSoftware>
					<instrumentID>0000000013085222</instrumentID>
				</source>
			</header>
			<scanAxisCenter>
				<position axis="2Theta" unit="deg">86.8400</position>
				<position axis="Omega" unit="deg">8.2314</position>
			</scanAxisCenter>
			<reflection>
				<material>Si [001]</material>
				<hkl>
					<h>2</h>
					<k>2</k>
					<l>4</l>
				</hkl>
				<unitCell>
					<alpha unit="deg">90.00000</alpha>
					<beta unit="deg">90.00000</beta>
					<gamma unit="deg">90.00000</gamma>
					<a unit="Angstrom">5.43119</a>
					<b unit="Angstrom">5.43119</b>
					<c unit="Angstrom">5.43119</c>
				</unitCell>
			</reflection>
			<dataPoints>
				<positions axis="2Theta" unit="deg">
					<startPosition>84.9800</startPosition>
					<endPosition>88.7000</endPosition>
				</positions>
				<positions axis="Omega" unit="deg">
					<startPosition>7.3014</startPosition>
					<endPosition>9.1614</endPosition>
				</positions>
				<positions axis="Phi" unit="deg">
					<commonPosition>0.00</commonPosition>
				</positions>
				<positions axis="Chi" unit="deg">
					<commonPosition>0.00</commonPosition>
				</positions>
				<positions axis="X" unit="mm">
					<commonPosition>0.00</commonPosition>
				</positions>
				<positions axis="Y" unit="mm">
					<commonPosition>0.00</commonPosition>
				</positions>
				<positions axis="Z" unit="mm">
					<commonPosition>8.416</commonPosition>
				</positions>
				<beamAttenuationFactors>1.00 1.00 1.00 1.00 1.00 1.00 1.00 1.00 1.00 1.00 1.00 1.00 1.00 1.00 1.00 1.00 1.00 1.00 1.00 1.00 1.00 1.00 1.00 1.00 1.00 1.00 1.00 1.00 1.00 1.00 1.00 1.00 1.00 1.00 1.00 1.00 1.00 1.00 1.00 1.00 1.00 1.00 1.00 1.00 1.00 1.00 1.00 1.00 1.00 1.00 1.00 1.00 1.00 1.00 1.00 1.00 1.00 1.00 1.00 1.00 1.00 1.00 1.00 1.00 1.00 1.00 1.00 1.00 1.00 1.00 1.00 1.00 1.00 1.00 1.00 1.00 1.00 1.00 1.00 1.00 1.00 1.00 1.00 1.00 1.00 1.00 1.00 1.00 1.00 1.00 1.00 1.00 1.00 1.00 1.00 1.00 1.00 1.00 1.00 1.00 1.00 1.00 1.00 1.00 1.00 1.00 1.00 1.00 1.00 1.00 1.00 1.00 1.00 1.00 1.00 1.00 1.00 1.00 1.00 1.00 1.00 1.00 1.00 1.00 1.00</beamAttenuationFactors>
				<commonCountingTime unit="seconds">0.50</commonCountingTime>
				<intensities unit="counts">0 0 0 1 0 0 1 0 0 1 0 0 1 0 0 1 1 0 2 4 7 2 7 8 10 17 32 47 72 101 84 57 55 55 36 27 24 15 10 16 14 9 10 5 5 3 2 4 3 3 3 2 0 3 1 1 2 2 1 2 4 0 1 1 1 0 1 0 0 0 1 1 0 2 2 1 2 1 0 0 0 1 2 0 4 2 1 3 1 6 3 1 3 6 6 12 11 20 30 50 82 103 92 98 87 57 47 28 12 18 6 7 7 7 4 2 2 1 1 1 0 2 1 2 1</intensities>
			</dataPoints>
		</scan>
		<scan appendNumber="0" mode="Continuous" scanAxis="Omega-2Theta" status="Completed">
			<header>
				<startTimeStamp>2016-02-08T12:12:18-08:00</startTimeStamp>
				<endTimeStamp>2016-02-08T12:13:43-08:00</endTimeStamp>
				<author>
					<name>user</name>
				</author>
				<source>
					<applicationSoftware version="4.2a">Data Collector</applicationSoftware>
					<instrumentControlSoftware version="2.2  20130918">XPERT-PRO</instrumentControlSoftware>
					<instrumentID>0000000013085222</instrumentID>
				</source>
			</header>
			<scanAxisCenter>
				<position axis="2Theta" unit="deg">86.8400</position>
				<position axis="Omega" unit="deg">8.2464</position>
			</scanAxisCenter>
			<reflection>
				<material>Si [001]</material>
				<hkl>
					<h>2</h>
					<k>2</k>
					<l>4</l>
				</hkl>
				<unitCell>
					<alpha unit="deg">90.00000</alpha>
					<beta unit="deg">90.00000</beta>
					<gamma unit="deg">90.00000</gamma>
					<a unit="Angstrom">5.43119</a>
					<b unit="Angstrom">5.43119</b>
					<c unit="Angstrom">5.43119</c>
				</unitCell>
			</reflection>
			<dataPoints>
				<positions axis="2Theta" unit="deg">
					<startPosition>84.9800</startPosition>
					<endPosition>88.7000</endPosition>
				</positions>
				<positions axis="Omega" unit="deg">
					<startPosition>7.3164</startPosition>
					<endPosition>9.1764</endPosition>
				</positions>
				<positions axis="Phi" unit="deg">
					<commonPosition>0.00</commonPosition>
				</positions>
				<positions axis="Chi" unit="deg">
					<commonPosition>0.00</commonPosition>
				</positions>
				<positions axis="X" unit="mm">
					<commonPosition>0.00</commonPosition>
				</positions>
				<positions axis="Y" unit="mm">
					<commonPosition>0.00</commonPosition>
				</positions>
				<positions axis="Z" unit="mm">
					<commonPosition>8.416</commonPosition>
				</positions>
				<beamAttenuationFactors>1.00 1.00 1.00 1.00 1.00 1.00 1.00 1.00 1.00 1.00 1.00 1.00 1.00 1.00 1.00 1.00 1.00 1.00 1.00 1.00 1.00 1.00 1.00 1.00 1.00 1.00 1.00 1.00 1.00 1.00 1.00 1.00 1.00 1.00 1.00 1.00 1.00 1.00 1.00 1.00 1.00 1.00 1.00 1.00 1.00 1.00 1.00 1.00 1.00 1.00 1.00 1.00 1.00 1.00 1.00 1.00 1.00 1.00 1.00 1.00 1.00 1.00 1.00 1.00 1.00 1.00 1.00 1.00 1.00 1.00 1.00 1.00 1.00 1.00 1.00 1.00 1.00 1.00 1.00 1.00 1.00 1.00 1.00 1.00 1.00 1.00 1.00 1.00 1.00 1.00 1.00 1.00 1.00 1.00 1.00 1.00 1.00 1.00 1.00 1.00 1.00 1.00 1.00 1.00 1.00 1.00 1.00 1.00 1.00 1.00 1.00 1.00 1.00 1.00 1.00 1.00 1.00 1.00 1.00 1.00 1.00 1.00 1.00 1.00 1.00</beamAttenuationFactors>
				<commonCountingTime unit="seconds">0.50</commonCountingTime>
				<intensities unit="counts">2 0 0 0 1 0 0 0 0 0 1 1 0 0 1 0 3 0 0 5 1 2 7 14 6 26 33 57 64 80 89 69 43 38 25 16 24 13 12 18 17 6 6 6 5 3 6 7 2 2 1 1 1 1 3 3 1 0 2 0 1 2 2 1 0 0 2 0 0 1 0 0 0 1 0 0 0 1 0 0 1 1 1 1 0 2 0 1 3 2 0 5 3 4 3 8 10 13 19 28 46 66 71 64 56 50 40 26 22 15 4 7 1 1 3 3 2 1 0 2 1 2 4 0 0</intensities>
			</dataPoints>
		</scan>
		<scan appendNumber="0" mode="Continuous" scanAxis="Omega-2Theta" status="Completed">
			<header>
				<startTimeStamp>2016-02-08T12:14:01-08:00</startTimeStamp>
				<endTimeStamp>2016-02-08T12:15:21-08:00</endTimeStamp>
				<author>
					<name>user</name>
				</author>
				<source>
					<applicationSoftware version="4.2a">Data Collector</applicationSoftware>
					<instrumentControlSoftware version="2.2  20130918">XPERT-PRO</instrumentControlSoftware>
					<instrumentID>0000000013085222</instrumentID>
				</source>
			</header>
			<scanAxisCenter>
				<position axis="2Theta" unit="deg">86.8400</position>
				<position axis="Omega" unit="deg">8.2614</position>
			</scanAxisCenter>
			<reflection>
				<material>Si [001]</material>
				<hkl>
					<h>2</h>
					<k>2</k>
					<l>4</l>
				</hkl>
				<unitCell>
					<alpha unit="deg">90.00000</alpha>
					<beta unit="deg">90.00000</beta>
					<gamma unit="deg">90.00000</gamma>
					<a unit="Angstrom">5.43119</a>
					<b unit="Angstrom">5.43119</b>
					<c unit="Angstrom">5.43119</c>
				</unitCell>
			</reflection>
			<dataPoints>
				<positions axis="2Theta" unit="deg">
					<startPosition>84.9800</startPosition>
					<endPosition>88.7000</endPosition>
				</positions>
				<positions axis="Omega" unit="deg">
					<startPosition>7.3314</startPosition>
					<endPosition>9.1914</endPosition>
				</positions>
				<positions axis="Phi" unit="deg">
					<commonPosition>0.00</commonPosition>
				</positions>
				<positions axis="Chi" unit="deg">
					<commonPosition>0.00</commonPosition>
				</positions>
				<positions axis="X" unit="mm">
					<commonPosition>0.00</commonPosition>
				</positions>
				<positions axis="Y" unit="mm">
					<commonPosition>0.00</commonPosition>
				</positions>
				<positions axis="Z" unit="mm">
					<commonPosition>8.416</commonPosition>
				</positions>
				<beamAttenuationFactors>1.00 1.00 1.00 1.00 1.00 1.00 1.00 1.00 1.00 1.00 1.00 1.00 1.00 1.00 1.00 1.00 1.00 1.00 1.00 1.00 1.00 1.00 1.00 1.00 1.00 1.00 1.00 1.00 1.00 1.00 1.00 1.00 1.00 1.00 1.00 1.00 1.00 1.00 1.00 1.00 1.00 1.00 1.00 1.00 1.00 1.00 1.00 1.00 1.00 1.00 1.00 1.00 1.00 1.00 1.00 1.00 1.00 1.00 1.00 1.00 1.00 1.00 1.00 1.00 1.00 1.00 1.00 1.00 1.00 1.00 1.00 1.00 1.00 1.00 1.00 1.00 1.00 1.00 1.00 1.00 1.00 1.00 1.00 1.00 1.00 1.00 1.00 1.00 1.00 1.00 1.00 1.00 1.00 1.00 1.00 1.00 1.00 1.00 1.00 1.00 1.00 1.00 1.00 1.00 1.00 1.00 1.00 1.00 1.00 1.00 1.00 1.00 1.00 1.00 1.00 1.00 1.00 1.00 1.00 1.00 1.00 1.00 1.00 1.00 1.00</beamAttenuationFactors>
				<commonCountingTime unit="seconds">0.50</commonCountingTime>
				<intensities unit="counts">0 0 0 0 0 0 0 0 0 0 0 1 1 0 0 1 2 4 1 5 2 1 0 5 9 13 32 54 71 94 80 53 40 34 29 16 26 20 22 10 2 8 7 5 2 8 6 3 3 1 2 3 2 1 2 2 1 0 0 1 1 2 0 3 0 1 2 1 0 0 0 0 1 3 3 1 0 4 1 2 1 0 0 2 1 0 1 1 0 2 2 7 4 3 5 11 5 12 13 29 27 43 50 48 49 32 31 28 11 9 9 4 4 4 2 1 5 1 2 1 3 1 2 0 0</intensities>
			</dataPoints>
		</scan>
		<scan appendNumber="0" mode="Continuous" scanAxis="Omega-2Theta" status="Completed">
			<header>
				<startTimeStamp>2016-02-08T12:15:37-08:00</startTimeStamp>
				<endTimeStamp>2016-02-08T12:16:57-08:00</endTimeStamp>
				<author>
					<name>user</name>
				</author>
				<source>
					<applicationSoftware version="4.2a">Data Collector</applicationSoftware>
					<instrumentControlSoftware version="2.2  20130918">XPERT-PRO</instrumentControlSoftware>
					<instrumentID>0000000013085222</instrumentID>
				</source>
			</header>
			<scanAxisCenter>
				<position axis="2Theta" unit="deg">86.8400</position>
				<position axis="Omega" unit="deg">8.2764</position>
			</scanAxisCenter>
			<reflection>
				<material>Si [001]</material>
				<hkl>
					<h>2</h>
					<k>2</k>
					<l>4</l>
				</hkl>
				<unitCell>
					<alpha unit="deg">90.00000</alpha>
					<beta unit="deg">90.00000</beta>
					<gamma unit="deg">90.00000</gamma>
					<a unit="Angstrom">5.43119</a>
					<b unit="Angstrom">5.43119</b>
					<c unit="Angstrom">5.43119</c>
				</unitCell>
			</reflection>
			<dataPoints>
				<positions axis="2Theta" unit="deg">
					<startPosition>84.9800</startPosition>
					<endPosition>88.7000</endPosition>
				</positions>
				<positions axis="Omega" unit="deg">
					<startPosition>7.3464</startPosition>
					<endPosition>9.2064</endPosition>
				</positions>
				<positions axis="Phi" unit="deg">
					<commonPosition>0.00</commonPosition>
				</positions>
				<positions axis="Chi" unit="deg">
					<commonPosition>0.00</commonPosition>
				</positions>
				<positions axis="X" unit="mm">
					<commonPosition>0.00</commonPosition>
				</positions>
				<positions axis="Y" unit="mm">
					<commonPosition>0.00</commonPosition>
				</positions>
				<positions axis="Z" unit="mm">
					<commonPosition>8.416</commonPosition>
				</positions>
				<beamAttenuationFactors>1.00 1.00 1.00 1.00 1.00 1.00 1.00 1.00 1.00 1.00 1.00 1.00 1.00 1.00 1.00 1.00 1.00 1.00 1.00 1.00 1.00 1.00 1.00 1.00 1.00 1.00 1.00 1.00 1.00 1.00 1.00 1.00 1.00 1.00 1.00 1.00 1.00 1.00 1.00 1.00 1.00 1.00 1.00 1.00 1.00 1.00 1.00 1.00 1.00 1.00 1.00 1.00 1.00 1.00 1.00 1.00 1.00 1.00 1.00 1.00 1.00 1.00 1.00 1.00 1.00 1.00 1.00 1.00 1.00 1.00 1.00 1.00 1.00 1.00 1.00 1.00 1.00 1.00 1.00 1.00 1.00 1.00 1.00 1.00 1.00 1.00 1.00 1.00 1.00 1.00 1.00 1.00 1.00 1.00 1.00 1.00 1.00 1.00 1.00 1.00 1.00 1.00 1.00 1.00 1.00 1.00 1.00 1.00 1.00 1.00 1.00 1.00 1.00 1.00 1.00 1.00 1.00 1.00 1.00 1.00 1.00 1.00 1.00 1.00 1.00</beamAttenuationFactors>
				<commonCountingTime unit="seconds">0.50</commonCountingTime>
				<intensities unit="counts">1 0 2 0 0 1 0 0 1 1 0 1 0 0 0 0 1 1 2 0 2 2 6 4 12 15 33 34 52 78 61 50 30 29 22 16 15 13 11 9 17 8 9 5 10 3 4 2 1 3 1 4 1 3 1 0 4 0 3 1 1 2 0 1 1 1 2 2 0 1 1 0 2 1 0 0 2 0 0 1 2 0 3 2 2 2 2 2 1 1 3 3 3 7 8 10 3 9 15 16 18 23 33 30 30 33 27 17 7 6 8 16 2 4 4 6 1 1 2 1 1 0 2 0 1</intensities>
			</dataPoints>
		</scan>
	</xrdMeasurement>
</xrdMeasurements>